Workbook

Sheet Preprocessing
A2: SQUATE PATTERN RECOGNIZATION | W2: Shape Recognizer
W3: Copyright (C)1994, Cheshire Engineering Corp
A5: TRAINING DATA
A6: Sl No | C6: Inputs Pattern | J6: TargetsSquare(Yes/No) | L6: Blob | N6: Input Matrix (Symbolic)
A9: 1 | C9: . | D9: . | E9: . | F9: . | G9: . | H9: . | J9: Yes | L9: No | N9: =IF(C9=".",-1,1) -> -1 | O9: =IF(D9=".",-1,1) -> -1 | P9: =IF(E9=".",-1,1) -> -1 | Q9: =IF(F9=".",-1,1) -> -1 | R9: =IF(G9=".",-1,1) -> -1 | S9: =IF(H9=".",-1,1) -> -1
C10: . | D10: X | E10: X | F10: X | G10: X | H10: . | N10: =IF(C10=".",-1,1) -> -1 | O10: =IF(D10=".",-1,1) -> 1 | P10: =IF(E10=".",-1,1) -> 1 | Q10: =IF(F10=".",-1,1) -> 1 | R10: =IF(G10=".",-1,1) -> 1 | S10: =IF(H10=".",-1,1) -> -1
C11: . | D11: X | E11: X | F11: X | G11: X | H11: . | N11: =IF(C11=".",-1,1) -> -1 | O11: =IF(D11=".",-1,1) -> 1 | P11: =IF(E11=".",-1,1) -> 1 | Q11: =IF(F11=".",-1,1) -> 1 | R11: =IF(G11=".",-1,1) -> 1 | S11: =IF(H11=".",-1,1) -> -1
C12: . | D12: X | E12: X | F12: X | G12: X | H12: . | N12: =IF(C12=".",-1,1) -> -1 | O12: =IF(D12=".",-1,1) -> 1 | P12: =IF(E12=".",-1,1) -> 1 | Q12: =IF(F12=".",-1,1) -> 1 | R12: =IF(G12=".",-1,1) -> 1 | S12: =IF(H12=".",-1,1) -> -1
C13: . | D13: X | E13: X | F13: X | G13: X | H13: . | N13: =IF(C13=".",-1,1) -> -1 | O13: =IF(D13=".",-1,1) -> 1 | P13: =IF(E13=".",-1,1) -> 1 | Q13: =IF(F13=".",-1,1) -> 1 | R13: =IF(G13=".",-1,1) -> 1 | S13: =IF(H13=".",-1,1) -> -1
C14: . | D14: . | E14: . | F14: . | G14: . | H14: . | N14: =IF(C14=".",-1,1) -> -1 | O14: =IF(D14=".",-1,1) -> -1 | P14: =IF(E14=".",-1,1) -> -1 | Q14: =IF(F14=".",-1,1) -> -1 | R14: =IF(G14=".",-1,1) -> -1 | S14: =IF(H14=".",-1,1) -> -1
A16: 2 | C16: . | D16: . | E16: . | F16: . | G16: X | H16: . | J16: No | L16: Yes | N16: =IF(C16=".",-1,1) -> -1 | O16: =IF(D16=".",-1,1) -> -1 | P16: =IF(E16=".",-1,1) -> -1 | Q16: =IF(F16=".",-1,1) -> -1 | R16: =IF(G16=".",-1,1) -> 1 | S16: =IF(H16=".",-1,1) -> -1
C17: . | D17: X | E17: X | F17: X | G17: X | H17: X | N17: =IF(C17=".",-1,1) -> -1 | O17: =IF(D17=".",-1,1) -> 1 | P17: =IF(E17=".",-1,1) -> 1 | Q17: =IF(F17=".",-1,1) -> 1 | R17: =IF(G17=".",-1,1) -> 1 | S17: =IF(H17=".",-1,1) -> 1
C18: . | D18: X | E18: . | F18: . | G18: . | H18: X | N18: =IF(C18=".",-1,1) -> -1 | O18: =IF(D18=".",-1,1) -> 1 | P18: =IF(E18=".",-1,1) -> -1 | Q18: =IF(F18=".",-1,1) -> -1 | R18: =IF(G18=".",-1,1) -> -1 | S18: =IF(H18=".",-1,1) -> 1
C19: . | D19: X | E19: X | F19: X | G19: X | H19: X | N19: =IF(C19=".",-1,1) -> -1 | O19: =IF(D19=".",-1,1) -> 1 | P19: =IF(E19=".",-1,1) -> 1 | Q19: =IF(F19=".",-1,1) -> 1 | R19: =IF(G19=".",-1,1) -> 1 | S19: =IF(H19=".",-1,1) -> 1
C20: . | D20: . | E20: X | F20: . | G20: . | H20: . | N20: =IF(C20=".",-1,1) -> -1 | O20: =IF(D20=".",-1,1) -> -1 | P20: =IF(E20=".",-1,1) -> 1 | Q20: =IF(F20=".",-1,1) -> -1 | R20: =IF(G20=".",-1,1) -> -1 | S20: =IF(H20=".",-1,1) -> -1
C21: . | D21: . | E21: . | F21: . | G21: . | H21: . | N21: =IF(C21=".",-1,1) -> -1 | O21: =IF(D21=".",-1,1) -> -1 | P21: =IF(E21=".",-1,1) -> -1 | Q21: =IF(F21=".",-1,1) -> -1 | R21: =IF(G21=".",-1,1) -> -1 | S21: =IF(H21=".",-1,1) -> -1
A23: 3 | C23: X | D23: X | E23: X | F23: X | G23: . | H23: . | J23: Yes | L23: No | N23: =IF(C23=".",-1,1) -> 1 | O23: =IF(D23=".",-1,1) -> 1 | P23: =IF(E23=".",-1,1) -> 1 | Q23: =IF(F23=".",-1,1) -> 1 | R23: =IF(G23=".",-1,1) -> -1 | S23: =IF(H23=".",-1,1) -> -1
C24: X | D24: X | E24: X | F24: X | G24: . | H24: . | N24: =IF(C24=".",-1,1) -> 1 | O24: =IF(D24=".",-1,1) -> 1 | P24: =IF(E24=".",-1,1) -> 1 | Q24: =IF(F24=".",-1,1) -> 1 | R24: =IF(G24=".",-1,1) -> -1 | S24: =IF(H24=".",-1,1) -> -1
C25: X | D25: X | E25: X | F25: X | G25: . | H25: . | N25: =IF(C25=".",-1,1) -> 1 | O25: =IF(D25=".",-1,1) -> 1 | P25: =IF(E25=".",-1,1) -> 1 | Q25: =IF(F25=".",-1,1) -> 1 | R25: =IF(G25=".",-1,1) -> -1 | S25: =IF(H25=".",-1,1) -> -1
C26: X | D26: X | E26: X | F26: X | G26: . | H26: . | N26: =IF(C26=".",-1,1) -> 1 | O26: =IF(D26=".",-1,1) -> 1 | P26: =IF(E26=".",-1,1) -> 1 | Q26: =IF(F26=".",-1,1) -> 1 | R26: =IF(G26=".",-1,1) -> -1 | S26: =IF(H26=".",-1,1) -> -1
C27: . | D27: . | E27: . | F27: . | G27: . | H27: . | N27: =IF(C27=".",-1,1) -> -1 | O27: =IF(D27=".",-1,1) -> -1 | P27: =IF(E27=".",-1,1) -> -1 | Q27: =IF(F27=".",-1,1) -> -1 | R27: =IF(G27=".",-1,1) -> -1 | S27: =IF(H27=".",-1,1) -> -1
C28: . | D28: . | E28: . | F28: . | G28: . | H28: . | N28: =IF(C28=".",-1,1) -> -1 | O28: =IF(D28=".",-1,1) -> -1 | P28: =IF(E28=".",-1,1) -> -1 | Q28: =IF(F28=".",-1,1) -> -1 | R28: =IF(G28=".",-1,1) -> -1 | S28: =IF(H28=".",-1,1) -> -1
A30: 4 | C30: . | D30: . | E30: . | F30: . | G30: . | H30: . | J30: No | L30: Yes | N30: =IF(C30=".",-1,1) -> -1 | O30: =IF(D30=".",-1,1) -> -1 | P30: =IF(E30=".",-1,1) -> -1 | Q30: =IF(F30=".",-1,1) -> -1 | R30: =IF(G30=".",-1,1) -> -1 | S30: =IF(H30=".",-1,1) -> -1
C31: X | D31: X | E31: X | F31: X | G31: X | H31: . | N31: =IF(C31=".",-1,1) -> 1 | O31: =IF(D31=".",-1,1) -> 1 | P31: =IF(E31=".",-1,1) -> 1 | Q31: =IF(F31=".",-1,1) -> 1 | R31: =IF(G31=".",-1,1) -> 1 | S31: =IF(H31=".",-1,1) -> -1
C32: X | D32: . | E32: X | F32: . | G32: X | H32: . | N32: =IF(C32=".",-1,1) -> 1 | O32: =IF(D32=".",-1,1) -> -1 | P32: =IF(E32=".",-1,1) -> 1 | Q32: =IF(F32=".",-1,1) -> -1 | R32: =IF(G32=".",-1,1) -> 1 | S32: =IF(H32=".",-1,1) -> -1
C33: X | D33: . | E33: X | F33: . | G33: X | H33: . | N33: =IF(C33=".",-1,1) -> 1 | O33: =IF(D33=".",-1,1) -> -1 | P33: =IF(E33=".",-1,1) -> 1 | Q33: =IF(F33=".",-1,1) -> -1 | R33: =IF(G33=".",-1,1) -> 1 | S33: =IF(H33=".",-1,1) -> -1
C34: X | D34: X | E34: X | F34: X | G34: X | H34: . | N34: =IF(C34=".",-1,1) -> 1 | O34: =IF(D34=".",-1,1) -> 1 | P34: =IF(E34=".",-1,1) -> 1 | Q34: =IF(F34=".",-1,1) -> 1 | R34: =IF(G34=".",-1,1) -> 1 | S34: =IF(H34=".",-1,1) -> -1
C35: . | D35: . | E35: . | F35: . | G35: . | H35: . | N35: =IF(C35=".",-1,1) -> -1 | O35: =IF(D35=".",-1,1) -> -1 | P35: =IF(E35=".",-1,1) -> -1 | Q35: =IF(F35=".",-1,1) -> -1 | R35: =IF(G35=".",-1,1) -> -1 | S35: =IF(H35=".",-1,1) -> -1
A37: 5 | C37: . | D37: . | E37: . | F37: . | G37: . | H37: . | J37: Yes | L37: No | N37: =IF(C37=".",-1,1) -> -1 | O37: =IF(D37=".",-1,1) -> -1 | P37: =IF(E37=".",-1,1) -> -1 | Q37: =IF(F37=".",-1,1) -> -1 | R37: =IF(G37=".",-1,1) -> -1 | S37: =IF(H37=".",-1,1) -> -1
C38: . | D38: . | E38: . | F38: . | G38: . | H38: . | N38: =IF(C38=".",-1,1) -> -1 | O38: =IF(D38=".",-1,1) -> -1 | P38: =IF(E38=".",-1,1) -> -1 | Q38: =IF(F38=".",-1,1) -> -1 | R38: =IF(G38=".",-1,1) -> -1 | S38: =IF(H38=".",-1,1) -> -1
C39: X | D39: X | E39: X | F39: X | G39: . | H39: . | N39: =IF(C39=".",-1,1) -> 1 | O39: =IF(D39=".",-1,1) -> 1 | P39: =IF(E39=".",-1,1) -> 1 | Q39: =IF(F39=".",-1,1) -> 1 | R39: =IF(G39=".",-1,1) -> -1 | S39: =IF(H39=".",-1,1) -> -1
C40: X | D40: X | E40: X | F40: X | G40: . | H40: . | N40: =IF(C40=".",-1,1) -> 1 | O40: =IF(D40=".",-1,1) -> 1 | P40: =IF(E40=".",-1,1) -> 1 | Q40: =IF(F40=".",-1,1) -> 1 | R40: =IF(G40=".",-1,1) -> -1 | S40: =IF(H40=".",-1,1) -> -1
C41: X | D41: X | E41: X | F41: X | G41: . | H41: . | N41: =IF(C41=".",-1,1) -> 1 | O41: =IF(D41=".",-1,1) -> 1 | P41: =IF(E41=".",-1,1) -> 1 | Q41: =IF(F41=".",-1,1) -> 1 | R41: =IF(G41=".",-1,1) -> -1 | S41: =IF(H41=".",-1,1) -> -1
C42: X | D42: X | E42: X | F42: X | G42: . | H42: . | N42: =IF(C42=".",-1,1) -> 1 | O42: =IF(D42=".",-1,1) -> 1 | P42: =IF(E42=".",-1,1) -> 1 | Q42: =IF(F42=".",-1,1) -> 1 | R42: =IF(G42=".",-1,1) -> -1 | S42: =IF(H42=".",-1,1) -> -1
A44: 6 | C44: . | D44: X | E44: . | F44: . | G44: . | H44: . | J44: No | L44: Yes | N44: =IF(C44=".",-1,1) -> -1 | O44: =IF(D44=".",-1,1) -> 1 | P44: =IF(E44=".",-1,1) -> -1 | Q44: =IF(F44=".",-1,1) -> -1 | R44: =IF(G44=".",-1,1) -> -1 | S44: =IF(H44=".",-1,1) -> -1
C45: X | D45: . | E45: X | F45: X | G45: X | H45: . | N45: =IF(C45=".",-1,1) -> 1 | O45: =IF(D45=".",-1,1) -> -1 | P45: =IF(E45=".",-1,1) -> 1 | Q45: =IF(F45=".",-1,1) -> 1 | R45: =IF(G45=".",-1,1) -> 1 | S45: =IF(H45=".",-1,1) -> -1
C46: X | D46: X | E46: X | F46: . | G46: X | H46: . | N46: =IF(C46=".",-1,1) -> 1 | O46: =IF(D46=".",-1,1) -> 1 | P46: =IF(E46=".",-1,1) -> 1 | Q46: =IF(F46=".",-1,1) -> -1 | R46: =IF(G46=".",-1,1) -> 1 | S46: =IF(H46=".",-1,1) -> -1
C47: X | D47: . | E47: X | F47: X | G47: X | H47: . | N47: =IF(C47=".",-1,1) -> 1 | O47: =IF(D47=".",-1,1) -> -1 | P47: =IF(E47=".",-1,1) -> 1 | Q47: =IF(F47=".",-1,1) -> 1 | R47: =IF(G47=".",-1,1) -> 1 | S47: =IF(H47=".",-1,1) -> -1
C48: X | D48: X | E48: X | F48: . | G48: X | H48: . | N48: =IF(C48=".",-1,1) -> 1 | O48: =IF(D48=".",-1,1) -> 1 | P48: =IF(E48=".",-1,1) -> 1 | Q48: =IF(F48=".",-1,1) -> -1 | R48: =IF(G48=".",-1,1) -> 1 | S48: =IF(H48=".",-1,1) -> -1
C49: . | D49: . | E49: . | F49: X | G49: . | H49: . | N49: =IF(C49=".",-1,1) -> -1 | O49: =IF(D49=".",-1,1) -> -1 | P49: =IF(E49=".",-1,1) -> -1 | Q49: =IF(F49=".",-1,1) -> 1 | R49: =IF(G49=".",-1,1) -> -1 | S49: =IF(H49=".",-1,1) -> -1
...

Sheet Training
A2: SQUATE PATTERN RECOGNIZATION
B5: Input Patterns
B6: Parttern | C6: 1,1 | D6: 1,2 | E6: 1,3 | F6: 1,4 | G6: 1,5 | H6: 1,6 | I6: 2,1 | J6: 2,2 | K6: 2,3 | L6: 2,4 | M6: 2,5 | N6: 2,6 | O6: 3,1 | P6: 3,2 | Q6: 3,3 | R6: 3,4 | S6: 3,5 | T6: 3,6 | U6: 4,1 | V6: 4,2 | W6: 4,3 | X6: 4,4 | Y6: 4,5 | Z6: 4,6 | AA6: 5,1 | AB6: 5,2 | AC6: 5,3 | AD6: 5,4 | AE6: 5,5 | AF6: 5,6 | AG6: 6,1 | AH6: 6,2 | AI6: 6,3 | AJ6: 6,4 | AK6: 6,5 | AL6: 6,6 | AM6: Target
B7: 1 | C7: =Preprocessing!N$9 -> -1 | D7: =Preprocessing!O$9 -> -1 | E7: =Preprocessing!P$9 -> -1 | F7: =Preprocessing!Q$9 -> -1 | G7: =Preprocessing!R$9 -> -1 | H7: =Preprocessing!S$9 -> -1 | I7: =Preprocessing!N$10 -> -1 | J7: =Preprocessing!O$10 -> 1 | K7: =Preprocessing!P$10 -> 1 | L7: =Preprocessing!Q$10 -> 1 | M7: =Preprocessing!R$10 -> 1 | N7: =Preprocessing!S$10 -> -1 | O7: =Preprocessing!N$11 -> -1 | P7: =Preprocessing!O$11 -> 1 | Q7: =Preprocessing!P$11 -> 1 | R7: =Preprocessing!Q$11 -> 1 | S7: =Preprocessing!R$11 -> 1 | T7: =Preprocessing!S$11 -> -1 | U7: =Preprocessing!N$12 -> -1 | V7: =Preprocessing!O$12 -> 1 | W7: =Preprocessing!P$12 -> 1 | X7: =Preprocessing!Q$12 -> 1 | Y7: =Preprocessing!R$12 -> 1 | Z7: =Preprocessing!S$12 -> -1 | AA7: =Preprocessing!N$13 -> -1 | AB7: =Preprocessing!O$13 -> 1 | AC7: =Preprocessing!P$13 -> 1 | AD7: =Preprocessing!Q$13 -> 1 | AE7: =Preprocessing!R$13 -> 1 | AF7: =Preprocessing!S$13 -> -1 | AG7: =Preprocessing!N$14 -> -1 | AH7: =Preprocessing!O$14 -> -1 | AI7: =Preprocessing!P$14 -> -1 | AJ7: =Preprocessing!Q$14 -> -1 | AK7: =Preprocessing!R$14 -> -1 | AL7: =Preprocessing!S$14 -> -1 | AM7: 1
B8: 2 | C8: =Preprocessing!N16 -> -1 | D8: =Preprocessing!O16 -> -1 | E8: =Preprocessing!P16 -> -1 | F8: =Preprocessing!Q16 -> -1 | G8: =Preprocessing!R16 -> 1 | H8: =Preprocessing!S16 -> -1 | I8: =Preprocessing!N17 -> -1 | J8: =Preprocessing!O17 -> 1 | K8: =Preprocessing!P17 -> 1 | L8: =Preprocessing!Q17 -> 1 | M8: =Preprocessing!R17 -> 1 | N8: =Preprocessing!S17 -> 1 | O8: =Preprocessing!N18 -> -1 | P8: =Preprocessing!O18 -> 1 | Q8: =Preprocessing!P18 -> -1 | R8: =Preprocessing!Q18 -> -1 | S8: =Preprocessing!R18 -> -1 | T8: =Preprocessing!S18 -> 1 | U8: =Preprocessing!N19 -> -1 | V8: =Preprocessing!O19 -> 1 | W8: =Preprocessing!P19 -> 1 | X8: =Preprocessing!Q19 -> 1 | Y8: =Preprocessing!R19 -> 1 | Z8: =Preprocessing!S19 -> 1 | AA8: =Preprocessing!N20 -> -1 | AB8: =Preprocessing!O20 -> -1 | AC8: =Preprocessing!P20 -> 1 | AD8: =Preprocessing!Q20 -> -1 | AE8: =Preprocessing!R20 -> -1 | AF8: =Preprocessing!S20 -> -1 | AG8: =Preprocessing!N21 -> -1 | AH8: =Preprocessing!O21 -> -1 | AI8: =Preprocessing!P21 -> -1 | AJ8: =Preprocessing!Q21 -> -1 | AK8: =Preprocessing!R21 -> -1 | AL8: =Preprocessing!S21 -> -1 | AM8: 0
B9: 3 | C9: =Preprocessing!N23 -> 1 | D9: =Preprocessing!O23 -> 1 | E9: =Preprocessing!P23 -> 1 | F9: =Preprocessing!Q23 -> 1 | G9: =Preprocessing!R23 -> -1 | H9: =Preprocessing!S23 -> -1 | I9: =Preprocessing!N24 -> 1 | J9: =Preprocessing!O24 -> 1 | K9: =Preprocessing!P24 -> 1 | L9: =Preprocessing!Q24 -> 1 | M9: =Preprocessing!R24 -> -1 | N9: =Preprocessing!S24 -> -1 | O9: =Preprocessing!N25 -> 1 | P9: =Preprocessing!O25 -> 1 | Q9: =Preprocessing!P25 -> 1 | R9: =Preprocessing!Q25 -> 1 | S9: =Preprocessing!R25 -> -1 | T9: =Preprocessing!S25 -> -1 | U9: =Preprocessing!N26 -> 1 | V9: =Preprocessing!O26 -> 1 | W9: =Preprocessing!P26 -> 1 | X9: =Preprocessing!Q26 -> 1 | Y9: =Preprocessing!R26 -> -1 | Z9: =Preprocessing!S26 -> -1 | AA9: =Preprocessing!N27 -> -1 | AB9: =Preprocessing!O27 -> -1 | AC9: =Preprocessing!P27 -> -1 | AD9: =Preprocessing!Q27 -> -1 | AE9: =Preprocessing!R27 -> -1 | AF9: =Preprocessing!S27 -> -1 | AG9: =Preprocessing!N28 -> -1 | AH9: =Preprocessing!O28 -> -1 | AI9: =Preprocessing!P28 -> -1 | AJ9: =Preprocessing!Q28 -> -1 | AK9: =Preprocessing!R28 -> -1 | AL9: =Preprocessing!S28 -> -1 | AM9: 1
B10: 4 | C10: =Preprocessing!N30 -> -1 | D10: =Preprocessing!O30 -> -1 | E10: =Preprocessing!P30 -> -1 | F10: =Preprocessing!Q30 -> -1 | G10: =Preprocessing!R30 -> -1 | H10: =Preprocessing!S30 -> -1 | I10: =Preprocessing!N31 -> 1 | J10: =Preprocessing!O31 -> 1 | K10: =Preprocessing!P31 -> 1 | L10: =Preprocessing!Q31 -> 1 | M10: =Preprocessing!R31 -> 1 | N10: =Preprocessing!S31 -> -1 | O10: =Preprocessing!N32 -> 1 | P10: =Preprocessing!O32 -> -1 | Q10: =Preprocessing!P32 -> 1 | R10: =Preprocessing!Q32 -> -1 | S10: =Preprocessing!R32 -> 1 | T10: =Preprocessing!S32 -> -1 | U10: =Preprocessing!N33 -> 1 | V10: =Preprocessing!O33 -> -1 | W10: =Preprocessing!P33 -> 1 | X10: =Preprocessing!Q33 -> -1 | Y10: =Preprocessing!R33 -> 1 | Z10: =Preprocessing!S33 -> -1 | AA10: =Preprocessing!N34 -> 1 | AB10: =Preprocessing!O34 -> 1 | AC10: =Preprocessing!P34 -> 1 | AD10: =Preprocessing!Q34 -> 1 | AE10: =Preprocessing!R34 -> 1 | AF10: =Preprocessing!S34 -> -1 | AG10: =Preprocessing!N35 -> -1 | AH10: =Preprocessing!O35 -> -1 | AI10: =Preprocessing!P35 -> -1 | AJ10: =Preprocessing!Q35 -> -1 | AK10: =Preprocessing!R35 -> -1 | AL10: =Preprocessing!S35 -> -1 | AM10: 0
B11: 5 | C11: =Preprocessing!N37 -> -1 | D11: =Preprocessing!O37 -> -1 | E11: =Preprocessing!P37 -> -1 | F11: =Preprocessing!Q37 -> -1 | G11: =Preprocessing!R37 -> -1 | H11: =Preprocessing!S37 -> -1 | I11: =Preprocessing!N38 -> -1 | J11: =Preprocessing!O38 -> -1 | K11: =Preprocessing!P38 -> -1 | L11: =Preprocessing!Q38 -> -1 | M11: =Preprocessing!R38 -> -1 | N11: =Preprocessing!S38 -> -1 | O11: =Preprocessing!N39 -> 1 | P11: =Preprocessing!O39 -> 1 | Q11: =Preprocessing!P39 -> 1 | R11: =Preprocessing!Q39 -> 1 | S11: =Preprocessing!R39 -> -1 | T11: =Preprocessing!S39 -> -1 | U11: =Preprocessing!N40 -> 1 | V11: =Preprocessing!O40 -> 1 | W11: =Preprocessing!P40 -> 1 | X11: =Preprocessing!Q40 -> 1 | Y11: =Preprocessing!R40 -> -1 | Z11: =Preprocessing!S40 -> -1 | AA11: =Preprocessing!N41 -> 1 | AB11: =Preprocessing!O41 -> 1 | AC11: =Preprocessing!P41 -> 1 | AD11: =Preprocessing!Q41 -> 1 | AE11: =Preprocessing!R41 -> -1 | AF11: =Preprocessing!S41 -> -1 | AG11: =Preprocessing!N42 -> 1 | AH11: =Preprocessing!O42 -> 1 | AI11: =Preprocessing!P42 -> 1 | AJ11: =Preprocessing!Q42 -> 1 | AK11: =Preprocessing!R42 -> -1 | AL11: =Preprocessing!S42 -> -1 | AM11: 1
B12: 6 | C12: =Preprocessing!N44 -> -1 | D12: =Preprocessing!O44 -> 1 | E12: =Preprocessing!P44 -> -1 | F12: =Preprocessing!Q44 -> -1 | G12: =Preprocessing!R44 -> -1 | H12: =Preprocessing!S44 -> -1 | I12: =Preprocessing!N45 -> 1 | J12: =Preprocessing!O45 -> -1 | K12: =Preprocessing!P45 -> 1 | L12: =Preprocessing!Q45 -> 1 | M12: =Preprocessing!R45 -> 1 | N12: =Preprocessing!S45 -> -1 | O12: =Preprocessing!N46 -> 1 | P12: =Preprocessing!O46 -> 1 | Q12: =Preprocessing!P46 -> 1 | R12: =Preprocessing!Q46 -> -1 | S12: =Preprocessing!R46 -> 1 | T12: =Preprocessing!S46 -> -1 | U12: =Preprocessing!N47 -> 1 | V12: =Preprocessing!O47 -> -1 | W12: =Preprocessing!P47 -> 1 | X12: =Preprocessing!Q47 -> 1 | Y12: =Preprocessing!R47 -> 1 | Z12: =Preprocessing!S47 -> -1 | AA12: =Preprocessing!N48 -> 1 | AB12: =Preprocessing!O48 -> 1 | AC12: =Preprocessing!P48 -> 1 | AD12: =Preprocessing!Q48 -> -1 | AE12: =Preprocessing!R48 -> 1 | AF12: =Preprocessing!S48 -> -1 | AG12: =Preprocessing!N49 -> -1 | AH12: =Preprocessing!O49 -> -1 | AI12: =Preprocessing!P49 -> -1 | AJ12: =Preprocessing!Q49 -> 1 | AK12: =Preprocessing!R49 -> -1 | AL12: =Preprocessing!S49 -> -1 | AM12: 0
B13: 7 | C13: =Preprocessing!N51 -> -1 | D13: =Preprocessing!O51 -> -1 | E13: =Preprocessing!P51 -> -1 | F13: =Preprocessing!Q51 -> -1 | G13: =Preprocessing!R51 -> -1 | H13: =Preprocessing!S51 -> -1 | I13: =Preprocessing!N52 -> -1 | J13: =Preprocessing!O52 -> -1 | K13: =Preprocessing!P52 -> -1 | L13: =Preprocessing!Q52 -> -1 | M13: =Preprocessing!R52 -> -1 | N13: =Preprocessing!S52 -> -1 | O13: =Preprocessing!N53 -> -1 | P13: =Preprocessing!O53 -> -1 | Q13: =Preprocessing!P53 -> 1 | R13: =Preprocessing!Q53 -> 1 | S13: =Preprocessing!R53 -> 1 | T13: =Preprocessing!S53 -> 1 | U13: =Preprocessing!N54 -> -1 | V13: =Preprocessing!O54 -> -1 | W13: =Preprocessing!P54 -> 1 | X13: =Preprocessing!Q54 -> 1 | Y13: =Preprocessing!R54 -> 1 | Z13: =Preprocessing!S54 -> 1 | AA13: =Preprocessing!N55 -> -1 | AB13: =Preprocessing!O55 -> -1 | AC13: =Preprocessing!P55 -> 1 | AD13: =Preprocessing!Q55 -> 1 | AE13: =Preprocessing!R55 -> 1 | AF13: =Preprocessing!S55 -> 1 | AG13: =Preprocessing!N56 -> -1 | AH13: =Preprocessing!O56 -> -1 | AI13: =Preprocessing!P56 -> 1 | AJ13: =Preprocessing!Q56 -> 1 | AK13: =Preprocessing!R56 -> 1 | AL13: =Preprocessing!S56 -> 1 | AM13: 1
B14: 8 | C14: =Preprocessing!N58 -> -1 | D14: =Preprocessing!O58 -> -1 | E14: =Preprocessing!P58 -> -1 | F14: =Preprocessing!Q58 -> -1 | G14: =Preprocessing!R58 -> -1 | H14: =Preprocessing!S58 -> -1 | I14: =Preprocessing!N59 -> -1 | J14: =Preprocessing!O59 -> 1 | K14: =Preprocessing!P59 -> 1 | L14: =Preprocessing!Q59 -> 1 | M14: =Preprocessing!R59 -> 1 | N14: =Preprocessing!S59 -> 1 | O14: =Preprocessing!N60 -> -1 | P14: =Preprocessing!O60 -> 1 | Q14: =Preprocessing!P60 -> -1 | R14: =Preprocessing!Q60 -> -1 | S14: =Preprocessing!R60 -> -1 | T14: =Preprocessing!S60 -> 1 | U14: =Preprocessing!N61 -> -1 | V14: =Preprocessing!O61 -> 1 | W14: =Preprocessing!P61 -> -1 | X14: =Preprocessing!Q61 -> 1 | Y14: =Preprocessing!R61 -> -1 | Z14: =Preprocessing!S61 -> 1 | AA14: =Preprocessing!N62 -> -1 | AB14: =Preprocessing!O62 -> 1 | AC14: =Preprocessing!P62 -> -1 | AD14: =Preprocessing!Q62 -> -1 | AE14: =Preprocessing!R62 -> -1 | AF14: =Preprocessing!S62 -> 1 | AG14: =Preprocessing!N63 -> -1 | AH14: =Preprocessing!O63 -> 1 | AI14: =Preprocessing!P63 -> 1 | AJ14: =Preprocessing!Q63 -> 1 | AK14: =Preprocessing!R63 -> 1 | AL14: =Preprocessing!S63 -> 1 | AM14: 0
B15: 9 | C15: =Preprocessing!N65 -> -1 | D15: =Preprocessing!O65 -> -1 | E15: =Preprocessing!P65 -> 1 | F15: =Preprocessing!Q65 -> 1 | G15: =Preprocessing!R65 -> 1 | H15: =Preprocessing!S65 -> 1 | I15: =Preprocessing!N66 -> -1 | J15: =Preprocessing!O66 -> -1 | K15: =Preprocessing!P66 -> 1 | L15: =Preprocessing!Q66 -> 1 | M15: =Preprocessing!R66 -> 1 | N15: =Preprocessing!S66 -> 1 | O15: =Preprocessing!N67 -> -1 | P15: =Preprocessing!O67 -> -1 | Q15: =Preprocessing!P67 -> 1 | R15: =Preprocessing!Q67 -> 1 | S15: =Preprocessing!R67 -> 1 | T15: =Preprocessing!S67 -> 1 | U15: =Preprocessing!N68 -> -1 | V15: =Preprocessing!O68 -> -1 | W15: =Preprocessing!P68 -> 1 | X15: =Preprocessing!Q68 -> 1 | Y15: =Preprocessing!R68 -> 1 | Z15: =Preprocessing!S68 -> 1 | AA15: =Preprocessing!N69 -> -1 | AB15: =Preprocessing!O69 -> -1 | AC15: =Preprocessing!P69 -> -1 | AD15: =Preprocessing!Q69 -> -1 | AE15: =Preprocessing!R69 -> -1 | AF15: =Preprocessing!S69 -> -1 | AG15: =Preprocessing!N70 -> -1 | AH15: =Preprocessing!O70 -> -1 | AI15: =Preprocessing!P70 -> -1 | AJ15: =Preprocessing!Q70 -> -1 | AK15: =Preprocessing!R70 -> -1 | AL15: =Preprocessing!S70 -> -1 | AM15: 1
B16: 10 | C16: =Preprocessing!N72 -> -1 | D16: =Preprocessing!O72 -> -1 | E16: =Preprocessing!P72 -> -1 | F16: =Preprocessing!Q72 -> 1 | G16: =Preprocessing!R72 -> 1 | H16: =Preprocessing!S72 -> -1 | I16: =Preprocessing!N73 -> -1 | J16: =Preprocessing!O73 -> -1 | K16: =Preprocessing!P73 -> -1 | L16: =Preprocessing!Q73 -> 1 | M16: =Preprocessing!R73 -> 1 | N16: =Preprocessing!S73 -> -1 | O16: =Preprocessing!N74 -> 1 | P16: =Preprocessing!O74 -> 1 | Q16: =Preprocessing!P74 -> 1 | R16: =Preprocessing!Q74 -> 1 | S16: =Preprocessing!R74 -> 1 | T16: =Preprocessing!S74 -> -1 | U16: =Preprocessing!N75 -> 1 | V16: =Preprocessing!O75 -> -1 | W16: =Preprocessing!P75 -> -1 | X16: =Preprocessing!Q75 -> -1 | Y16: =Preprocessing!R75 -> 1 | Z16: =Preprocessing!S75 -> -1 | AA16: =Preprocessing!N76 -> 1 | AB16: =Preprocessing!O76 -> -1 | AC16: =Preprocessing!P76 -> -1 | AD16: =Preprocessing!Q76 -> -1 | AE16: =Preprocessing!R76 -> 1 | AF16: =Preprocessing!S76 -> -1 | AG16: =Preprocessing!N77 -> 1 | AH16: =Preprocessing!O77 -> 1 | AI16: =Preprocessing!P77 -> 1 | AJ16: =Preprocessing!Q77 -> 1 | AK16: =Preprocessing!R77 -> 1 | AL16: =Preprocessing!S77 -> -1 | AM16: 0
B18: INPUT LAYER (INDEX TABLE)
B19: obs1 | C19: 1 | D19: 2 | E19: 3 | F19: 4 | G19: 5 | H19: 6 | I19: 7 | J19: 8 | K19: 9 | L19: 10 | M19: 11 | N19: 12 | O19: 13 | P19: 14 | Q19: 15 | R19: 16 | S19: 17 | T19: 18 | U19: 19 | V19: 20 | W19: 21 | X19: 22 | Y19: 23 | Z19: 24 | AA19: 25 | AB19: 26 | AC19: 27 | AD19: 28 | AE19: 29 | AF19: 30 | AG19: 31 | AH19: 32 | AI19: 33 | AJ19: 34 | AK19: 35 | AL19: 36
B20: 4 | C20: =INDEX($C$7:$AL$16,$B$20,C19) -> -1 | D20: =INDEX($C$7:$AL$16,$B$20,D19) -> -1 | E20: =INDEX($C$7:$AL$16,$B$20,E19) -> -1 | F20: =INDEX($C$7:$AL$16,$B$20,F19) -> -1 | G20: =INDEX($C$7:$AL$16,$B$20,G19) -> -1 | H20: =INDEX($C$7:$AL$16,$B$20,H19) -> -1 | I20: =INDEX($C$7:$AL$16,$B$20,I19) -> 1 | J20: =INDEX($C$7:$AL$16,$B$20,J19) -> 1 | ... AL20: =INDEX($C$7:$AL$16,$B$20,AL19) -> -1
B23: HIDDEN LAYER
C24: Bias | D24: weight 1 | E24: weight 2 | F24: weight 3 | G24: weight 4 | H24: weight 5 | I24: weight 6 | J24: response | P24: WHAT IF DATA TABLE
B25: neuron 1 | C25: 11.364518 | D25: 2.3765336 | E25: 3.0984878 | F25: 2.3765135 | G25: 12.376349 | H25: 5.7622892 | I25: 2.376527 | J25: =1/(1+EXP(-(C25+SUMPRODUCT(D25:I25,$C$20:$H$20)))) -> 4.1309141e-08 | P25: obs | Q25: response | R25: actual | S25: diff^2
B26: neuron 2 | C26: 22.548893 | D26: -9.08173 | E26: -6.9173402 | F26: -9.67464 | G26: -4.0496036 | H26: -5.6424855 | I26: -9.9597209 | J26: =1/(1+EXP(-(C26+SUMPRODUCT(D26:I26,$I$20:$N$20)))) -> 0.054311071 | P26: 1 | Q26: =E40 -> 8.373853e-53 | R26: =I40 -> 0 | S26: =IFERROR((Q26-R26)^2,9999999) -> 7.0121414e-105
B27: neuron 3 | C27: -0.045516323 | D27: 10.619344 | E27: -6.1295611 | F27: 4.2282955 | G27: -10.612896 | H27: 9.4142516 | I27: -8.8982288 | J27: =1/(1+EXP(-(C27+SUMPRODUCT(D27:I27,$O$20:$T$20)))) -> 1 | P27: 2 | Q27: 5.2718062e-07 | R27: 0 | S27: =IFERROR((Q27-R27)^2,9999999) -> 2.779194e-13
B28: neuron 4 | C28: -6.6078953 | D28: 9.8987659 | E28: -10.367002 | F28: -25.623128 | G28: -25.78471 | H28: -2.3159067 | I28: -18.58389 | J28: =1/(1+EXP(-(C28+SUMPRODUCT(D28:I28,$U$20:$Z$20)))) -> 1 | P28: 3 | Q28: 1 | R28: 1 | S28: =IFERROR((Q28-R28)^2,9999999) -> 0
B29: neuron 5 | C29: 0.78884212 | D29: -8.8738229 | E29: -27.481321 | F29: -26.592396 | G29: 10.410059 | H29: 16.409575 | I29: -9.4058672 | J29: =1/(1+EXP(-(C29+SUMPRODUCT(D29:I29,$AA$20:$AF$20)))) -> 5.4620572e-12 | P29: 4 | Q29: 8.373853e-53 | R29: 0 | S29: =IFERROR((Q29-R29)^2,9999999) -> 7.0121414e-105
B30: neuron 6 | C30: -9.9825854 | D30: 0.89561175 | E30: -99 | F30: 1.261444 | G30: 1.3057704 | H30: 0.44725008 | I30: -0.452756 | J30: =1/(1+EXP(-(C30+SUMPRODUCT(D30:I30,$AG$20:$AL$20)))) -> 1 | P30: 5 | Q30: 0.99999803 | R30: 1 | S30: =IFERROR((Q30-R30)^2,9999999) -> 3.8701634e-12
P31: 6 | Q31: 0.00015010829 | R31: 0 | S31: =IFERROR((Q31-R31)^2,9999999) -> 2.25325e-08
P32: 7 | Q32: 1 | R32: 1 | S32: =IFERROR((Q32-R32)^2,9999999) -> 0
B33: Output layer | P33: 8 | Q33: 0.00023274282 | R33: 0 | S33: =IFERROR((Q33-R33)^2,9999999) -> 5.4169222e-08
B34: Layer 2 | C34: n1 | P34: 9 | Q34: 1 | R34: 1 | S34: =IFERROR((Q34-R34)^2,9999999) -> 0
B35: bias | C35: -8.5921081 | P35: 10 | Q35: 4.291034e-22 | R35: 0 | S35: =IFERROR((Q35-R35)^2,9999999) -> 1.8412973e-43
B36: w1 | C36: 4.2866107 | P36: Total Sum of Diff^2 = | S36: =SUM(S26:S35) -> 7.670587e-08
B37: w2 | C37: 23.085265
B38: w3 | C38: -17.148439
B39: w4 | C39: -89.27672 | E39: Response | I39: Actual Value
B40: w5 | C40: 38.445045 | E40: =1/(1+EXP(-(C35+SUMPRODUCT(C36:C41,$J$25:$J$30)))) -> 8.373853e-53 | I40: =INDEX(AM7:$AM$16,B20,1) -> 0
B41: w6 | C41: -6.1484146
