Workbook

Sheet Input
A2: Non Linear PSVM Problem
A5: Input Data Points | F5: Normalized Data Points
A6: INDEX | B6: X1 | C6: X2 | D6: CLASS | F6: INDEX | G6: X1 | H6: X2 | I6: CLASS
A7: 1 | B7: 0 | C7: 0 | D7: 1 | F7: =A7 -> 1 | G7: =(B7-B$17)/B$18 -> -1.7985617 | H7: =(C7-C$17)/C$18 -> -1.6730299 | I7: =D7 -> 1
A8: 2 | B8: 3 | C8: 4 | D8: 1 | F8: =A8 -> 2 | G8: =(B8-B$17)/B$18 -> -1.079137 | H8: =(C8-C$17)/C$18 -> -0.59365578 | I8: =D8 -> 1
A9: 3 | B9: 5 | C9: 9 | D9: 1 | F9: =A9 -> 3 | G9: =(B9-B$17)/B$18 -> -0.59952058 | H9: =(C9-C$17)/C$18 -> 0.7555619 | I9: =D9 -> 1
A10: 4 | B10: 12 | C10: 1 | D10: 1 | F10: =A10 -> 4 | G10: =(B10-B$17)/B$18 -> 1.079137 | H10: =(C10-C$17)/C$18 -> -1.4031864 | I10: =D10 -> 1
A11: 5 | B11: 8 | C11: 7 | D11: 1 | F11: =A11 -> 5 | G11: =(B11-B$17)/B$18 -> 0.11990412 | H11: =(C11-C$17)/C$18 -> 0.21587483 | I11: =D11 -> 1
A12: 6 | B12: 9 | C12: 8 | D12: -1 | F12: =A12 -> 6 | G12: =(B12-B$17)/B$18 -> 0.35971235 | H12: =(C12-C$17)/C$18 -> 0.48571836 | I12: =D12 -> -1
A13: 7 | B13: 6 | C13: 12 | D13: -1 | F13: =A13 -> 7 | G13: =(B13-B$17)/B$18 -> -0.35971235 | H13: =(C13-C$17)/C$18 -> 1.5650925 | I13: =D13 -> -1
A14: 8 | B14: 10 | C14: 8 | D14: -1 | F14: =A14 -> 8 | G14: =(B14-B$17)/B$18 -> 0.59952058 | H14: =(C14-C$17)/C$18 -> 0.48571836 | I14: =D14 -> -1
A15: 9 | B15: 8 | C15: 5 | D15: -1 | F15: =A15 -> 9 | G15: =(B15-B$17)/B$18 -> 0.11990412 | H15: =(C15-C$17)/C$18 -> -0.32381224 | I15: =D15 -> -1
A16: 10 | B16: 14 | C16: 8 | D16: -1 | F16: =A16 -> 10 | G16: =(B16-B$17)/B$18 -> 1.5587535 | H16: =(C16-C$17)/C$18 -> 0.48571836 | I16: =D16 -> -1
A17: Mean | B17: =AVERAGE(B7:B16) -> 7.5 | C17: =AVERAGE(C7:C16) -> 6.2
A18: SD | B18: =STDEV(B7:B16) -> 4.1699987 | C18: =STDEV(C7:C16) -> 3.7058512

Sheet Non Linear Calculation
A2: KERNEL TRICK
B10: Index | C10: X1 | D10: X2 | F10: First | H10: Second | J10: Kernel function
C11: 1 | D11: 2 | F11: =INDEX(Input!$G$7:$H$16,'Non Linear Calculation'!$C$11,1) -> -1.7985617 | G11: =INDEX(Input!$G$7:$H$16,'Non Linear Calculation'!$C$11,2) -> -1.6730299 | H11: =INDEX(Input!$G$7:$H$16,'Non Linear Calculation'!$D$11,1) -> -1.079137 | I11: =INDEX(Input!$G$7:$H$16,'Non Linear Calculation'!$D$11,2) -> -0.59365578 | J11: {=(MMULT(F11:G11,TRANSPOSE(H11:I11))+1)^4} -> 239.54157
A15: What if Table
A16: =J11 -> 239.54157 | B16: 1 | C16: 2 | D16: 3 | E16: 4 | F16: 5 | G16: 6 | H16: 7 | I16: 8 | J16: 9 | K16: 10
A17: 1 | B17: 2447.7849 | C17: 239.54157 | D17: 0.43945882 | E17: 3.9154266 | F17: 0.032070116 | G17: 0.044613673 | H17: 0.89071461 | I17: 0.62995318 | J17: 3.0923984 | K17: 46.842611
A18: 2 | B18: 239.54157 | C18: 40.133586 | D18: 2.0627086 | E18: 0.19968038 | F18: 0.30385949 | G18: 0.010948244 | H18: 0.044406872 | I18: 1.7507786e-05 | J18: 1.2760616 | K18: 0.88696653
A19: 3 | B19: 0.43945882 | C19: 2.0627086 | D19: 13.883472 | E19: 0.2500739 | F19: 1.4179214 | G19: 1.7571439 | H19: 33.077033 | I19: 1.0306066 | J19: 0.21819221 | K19: 0.034985348
A20: 4 | B20: 3.9154266 | C20: 0.19968038 | D20: 0.2500739 | E20: 291.9165 | F20: 0.46658431 | G20: 0.24932008 | H20: 6.3000597 | I20: 0.86865994 | J20: 6.2915778 | K20: 16.017775
A21: 5 | B21: 0.032070116 | C21: 0.30385949 | D21: 1.4179214 | E21: 0.46658431 | F21: 1.2671472 | G21: 1.7367824 | H21: 2.8100949 | I21: 1.917437 | J21: 0.79571983 | K21: 2.7843322
A22: 6 | B22: 0.044613673 | C22: 0.010948244 | D22: 1.7571439 | E22: 0.24932008 | F22: 1.7367824 | G22: 3.4748161 | H22: 7.0730071 | I22: 4.4397718 | J22: 0.61579996 | K22: 10.419094
A23: 7 | B23: 0.89071461 | C23: 0.044406872 | D23: 33.077033 | E23: 6.3000597 | F23: 2.8100949 | G23: 7.0730071 | H23: 164.0597 | I23: 5.6910941 | J23: 0.041032826 | K23: 2.0700861
A24: 8 | B24: 0.62995318 | C24: 1.7507786e-05 | D24: 1.0306066 | E24: 0.86865994 | F24: 1.917437 | G24: 4.4397718 | H24: 5.6910941 | I24: 6.4777012 | J24: 0.69973131 | K24: 22.191202
A25: 9 | B25: 3.0923984 | C25: 1.2760616 | D25: 0.21819221 | E25: 6.2915778 | F25: 0.79571983 | G25: 0.61579996 | H25: 0.041032826 | I25: 0.69973131 | J25: 1.5692043 | K25: 1.1238462
A26: 10 | B26: 46.842611 | C26: 0.88696653 | D26: 0.034985348 | E26: 16.017775 | F26: 2.7843322 | G26: 10.419094 | H26: 2.0700861 | I26: 22.191202 | J26: 1.1238462 | K26: 180.5497
A34: Augmented Matrix (K-e)
A35: =B17 -> 2447.7849 | B35: =C17 -> 239.54157 | C35: =D17 -> 0.43945882 | D35: =E17 -> 3.9154266 | E35: =F17 -> 0.032070116 | F35: =G17 -> 0.044613673 | G35: =H17 -> 0.89071461 | H35: =I17 -> 0.62995318 | ... J35: =K17 -> 46.842611 | K35: -1
A36: =B18 -> 239.54157 | B36: =C18 -> 40.133586 | C36: =D18 -> 2.0627086 | D36: =E18 -> 0.19968038 | E36: =F18 -> 0.30385949 | F36: =G18 -> 0.010948244 | G36: =H18 -> 0.044406872 | H36: =I18 -> 1.7507786e-05 | ... J36: =K18 -> 0.88696653 | K36: -1
A37: =B19 -> 0.43945882 | B37: =C19 -> 2.0627086 | C37: =D19 -> 13.883472 | D37: =E19 -> 0.2500739 | E37: =F19 -> 1.4179214 | F37: =G19 -> 1.7571439 | G37: =H19 -> 33.077033 | H37: =I19 -> 1.0306066 | ... J37: =K19 -> 0.034985348 | K37: -1
A38: =B20 -> 3.9154266 | B38: =C20 -> 0.19968038 | C38: =D20 -> 0.2500739 | D38: =E20 -> 291.9165 | E38: =F20 -> 0.46658431 | F38: =G20 -> 0.24932008 | G38: =H20 -> 6.3000597 | H38: =I20 -> 0.86865994 | ... J38: =K20 -> 16.017775 | K38: -1
A39: =B21 -> 0.032070116 | B39: =C21 -> 0.30385949 | C39: =D21 -> 1.4179214 | D39: =E21 -> 0.46658431 | E39: =F21 -> 1.2671472 | F39: =G21 -> 1.7367824 | G39: =H21 -> 2.8100949 | H39: =I21 -> 1.917437 | ... J39: =K21 -> 2.7843322 | K39: -1
A40: =B22 -> 0.044613673 | B40: =C22 -> 0.010948244 | C40: =D22 -> 1.7571439 | D40: =E22 -> 0.24932008 | E40: =F22 -> 1.7367824 | F40: =G22 -> 3.4748161 | G40: =H22 -> 7.0730071 | H40: =I22 -> 4.4397718 | ... J40: =K22 -> 10.419094 | K40: -1
A41: =B23 -> 0.89071461 | B41: =C23 -> 0.044406872 | C41: =D23 -> 33.077033 | D41: =E23 -> 6.3000597 | E41: =F23 -> 2.8100949 | F41: =G23 -> 7.0730071 | G41: =H23 -> 164.0597 | H41: =I23 -> 5.6910941 | ... J41: =K23 -> 2.0700861 | K41: -1
A42: =B24 -> 0.62995318 | B42: =C24 -> 1.7507786e-05 | C42: =D24 -> 1.0306066 | D42: =E24 -> 0.86865994 | E42: =F24 -> 1.917437 | F42: =G24 -> 4.4397718 | G42: =H24 -> 5.6910941 | H42: =I24 -> 6.4777012 | ... J42: =K24 -> 22.191202 | K42: -1
A43: =B25 -> 3.0923984 | B43: =C25 -> 1.2760616 | C43: =D25 -> 0.21819221 | D43: =E25 -> 6.2915778 | E43: =F25 -> 0.79571983 | F43: =G25 -> 0.61579996 | G43: =H25 -> 0.041032826 | H43: =I25 -> 0.69973131 | ... J43: =K25 -> 1.1238462 | K43: -1
A44: =B26 -> 46.842611 | B44: =C26 -> 0.88696653 | C44: =D26 -> 0.034985348 | D44: =E26 -> 16.017775 | E44: =F26 -> 2.7843322 | F44: =G26 -> 10.419094 | G44: =H26 -> 2.0700861 | H44: =I26 -> 22.191202 | ... J44: =K26 -> 180.5497 | K44: -1
E49: x1 | F49: x2 | G49: D
D50: index | E50: 8 | F50: 8 | G50: =IF(E50=F50,INDEX(Input!$D$7:$D$16,E50,1),0) -> -1
A52: Diagonal Matrix D having Class values
A53: =G50 -> -1 | B53: 1 | C53: 2 | D53: 3 | E53: 4 | F53: 5 | G53: 6 | H53: 7 | I53: 8 | J53: 9 | K53: 10
A54: 1 | B54: 1 | C54: 0 | D54: 0 | E54: 0 | F54: 0 | G54: 0 | H54: 0 | I54: 0 | J54: 0 | K54: 0
A55: 2 | B55: 0 | C55: 1 | D55: 0 | E55: 0 | F55: 0 | G55: 0 | H55: 0 | I55: 0 | J55: 0 | K55: 0
A56: 3 | B56: 0 | C56: 0 | D56: 1 | E56: 0 | F56: 0 | G56: 0 | H56: 0 | I56: 0 | J56: 0 | K56: 0
A57: 4 | B57: 0 | C57: 0 | D57: 0 | E57: 1 | F57: 0 | G57: 0 | H57: 0 | I57: 0 | J57: 0 | K57: 0
A58: 5 | B58: 0 | C58: 0 | D58: 0 | E58: 0 | F58: 1 | G58: 0 | H58: 0 | I58: 0 | J58: 0 | K58: 0
A59: 6 | B59: 0 | C59: 0 | D59: 0 | E59: 0 | F59: 0 | G59: -1 | H59: 0 | I59: 0 | J59: 0 | K59: 0
A60: 7 | B60: 0 | C60: 0 | D60: 0 | E60: 0 | F60: 0 | G60: 0 | H60: -1 | I60: 0 | J60: 0 | K60: 0
A61: 8 | B61: 0 | C61: 0 | D61: 0 | E61: 0 | F61: 0 | G61: 0 | H61: 0 | I61: -1 | J61: 0 | K61: 0
A62: 9 | B62: 0 | C62: 0 | D62: 0 | E62: 0 | F62: 0 | G62: 0 | H62: 0 | I62: 0 | J62: -1 | K62: 0
A63: 10 | B63: 0 | C63: 0 | D63: 0 | E63: 0 | F63: 0 | G63: 0 | H63: 0 | I63: 0 | J63: 0 | K63: -1
...

Sheet Non Linear Prediction
A2: PREDICTION FUNCTION
A16: Prediction to training data | I16: Kernel Matrix with respect to new data
A17: INDEX | B17: X1 | C17: X2 | D17: Actual CLASS | E17: Predicted | F17: True/false | I17: 1 | J17: 2 | K17: 3 | L17: 4 | M17: 5 | N17: 6 | O17: 7 | P17: 8 | Q17: 9 | R17: 10
A18: 1 | B18: =Input!G7 -> -1.7985617 | C18: =Input!H7 -> -1.6730299 | D18: =Input!I7 -> 1 | E18: =S18 -> 1 | F18: =IF(D18=E18,TRUE,FALSE) -> TRUE | H18: 1 | I18: ='Non Linear Calculation'!B17 -> 2447.7849 | J18: ='Non Linear Calculation'!C17 -> 239.54157 | K18: ='Non Linear Calculation'!D17 -> 0.43945882 | L18: ='Non Linear Calculation'!E17 -> 3.9154266 | M18: ='Non Linear Calculation'!F17 -> 0.032070116 | N18: ='Non Linear Calculation'!G17 -> 0.044613673 | O18: ='Non Linear Calculation'!H17 -> 0.89071461 | P18: ='Non Linear Calculation'!I17 -> 0.62995318 | ... R18: ='Non Linear Calculation'!K17 -> 46.842611 | S18: {=SIGN(MMULT(I18:R18,'Non Linear Calculation'!$D$155:$D$164)-'Non Linear Calculation'!$E$155)} -> 1
A19: 2 | B19: =Input!G8 -> -1.079137 | C19: =Input!H8 -> -0.59365578 | D19: =Input!I8 -> 1 | E19: =S19 -> 1 | F19: =IF(D19=E19,TRUE,FALSE) -> TRUE | H19: 2 | I19: ='Non Linear Calculation'!B18 -> 239.54157 | J19: ='Non Linear Calculation'!C18 -> 40.133586 | K19: ='Non Linear Calculation'!D18 -> 2.0627086 | L19: ='Non Linear Calculation'!E18 -> 0.19968038 | M19: ='Non Linear Calculation'!F18 -> 0.30385949 | N19: ='Non Linear Calculation'!G18 -> 0.010948244 | O19: ='Non Linear Calculation'!H18 -> 0.044406872 | P19: ='Non Linear Calculation'!I18 -> 1.7507786e-05 | ... R19: ='Non Linear Calculation'!K18 -> 0.88696653 | S19: {=SIGN(MMULT(I19:R19,'Non Linear Calculation'!$D$155:$D$164)-'Non Linear Calculation'!$E$155)} -> 1
A20: 3 | B20: =Input!G9 -> -0.59952058 | C20: =Input!H9 -> 0.7555619 | D20: =Input!I9 -> 1 | E20: =S20 -> 1 | F20: =IF(D20=E20,TRUE,FALSE) -> TRUE | H20: 3 | I20: ='Non Linear Calculation'!B19 -> 0.43945882 | J20: ='Non Linear Calculation'!C19 -> 2.0627086 | K20: ='Non Linear Calculation'!D19 -> 13.883472 | L20: ='Non Linear Calculation'!E19 -> 0.2500739 | M20: ='Non Linear Calculation'!F19 -> 1.4179214 | N20: ='Non Linear Calculation'!G19 -> 1.7571439 | O20: ='Non Linear Calculation'!H19 -> 33.077033 | P20: ='Non Linear Calculation'!I19 -> 1.0306066 | ... R20: ='Non Linear Calculation'!K19 -> 0.034985348 | S20: {=SIGN(MMULT(I20:R20,'Non Linear Calculation'!$D$155:$D$164)-'Non Linear Calculation'!$E$155)} -> 1
A21: 4 | B21: =Input!G10 -> 1.079137 | C21: =Input!H10 -> -1.4031864 | D21: =Input!I10 -> 1 | E21: =S21 -> 1 | F21: =IF(D21=E21,TRUE,FALSE) -> TRUE | H21: 4 | I21: ='Non Linear Calculation'!B20 -> 3.9154266 | J21: ='Non Linear Calculation'!C20 -> 0.19968038 | K21: ='Non Linear Calculation'!D20 -> 0.2500739 | L21: ='Non Linear Calculation'!E20 -> 291.9165 | M21: ='Non Linear Calculation'!F20 -> 0.46658431 | N21: ='Non Linear Calculation'!G20 -> 0.24932008 | O21: ='Non Linear Calculation'!H20 -> 6.3000597 | P21: ='Non Linear Calculation'!I20 -> 0.86865994 | ... R21: ='Non Linear Calculation'!K20 -> 16.017775 | S21: {=SIGN(MMULT(I21:R21,'Non Linear Calculation'!$D$155:$D$164)-'Non Linear Calculation'!$E$155)} -> 1
A22: 5 | B22: =Input!G11 -> 0.11990412 | C22: =Input!H11 -> 0.21587483 | D22: =Input!I11 -> 1 | E22: =S22 -> -1 | F22: =IF(D22=E22,TRUE,FALSE) -> FALSE | H22: 5 | I22: ='Non Linear Calculation'!B21 -> 0.032070116 | J22: ='Non Linear Calculation'!C21 -> 0.30385949 | K22: ='Non Linear Calculation'!D21 -> 1.4179214 | L22: ='Non Linear Calculation'!E21 -> 0.46658431 | M22: ='Non Linear Calculation'!F21 -> 1.2671472 | N22: ='Non Linear Calculation'!G21 -> 1.7367824 | O22: ='Non Linear Calculation'!H21 -> 2.8100949 | P22: ='Non Linear Calculation'!I21 -> 1.917437 | ... R22: ='Non Linear Calculation'!K21 -> 2.7843322 | S22: {=SIGN(MMULT(I22:R22,'Non Linear Calculation'!$D$155:$D$164)-'Non Linear Calculation'!$E$155)} -> -1
A23: 6 | B23: =Input!G12 -> 0.35971235 | C23: =Input!H12 -> 0.48571836 | D23: =Input!I12 -> -1 | E23: =S23 -> -1 | F23: =IF(D23=E23,TRUE,FALSE) -> TRUE | H23: 6 | I23: ='Non Linear Calculation'!B22 -> 0.044613673 | J23: ='Non Linear Calculation'!C22 -> 0.010948244 | K23: ='Non Linear Calculation'!D22 -> 1.7571439 | L23: ='Non Linear Calculation'!E22 -> 0.24932008 | M23: ='Non Linear Calculation'!F22 -> 1.7367824 | N23: ='Non Linear Calculation'!G22 -> 3.4748161 | O23: ='Non Linear Calculation'!H22 -> 7.0730071 | P23: ='Non Linear Calculation'!I22 -> 4.4397718 | ... R23: ='Non Linear Calculation'!K22 -> 10.419094 | S23: {=SIGN(MMULT(I23:R23,'Non Linear Calculation'!$D$155:$D$164)-'Non Linear Calculation'!$E$155)} -> -1
A24: 7 | B24: =Input!G13 -> -0.35971235 | C24: =Input!H13 -> 1.5650925 | D24: =Input!I13 -> -1 | E24: =S24 -> -1 | F24: =IF(D24=E24,TRUE,FALSE) -> TRUE | H24: 7 | I24: ='Non Linear Calculation'!B23 -> 0.89071461 | J24: ='Non Linear Calculation'!C23 -> 0.044406872 | K24: ='Non Linear Calculation'!D23 -> 33.077033 | L24: ='Non Linear Calculation'!E23 -> 6.3000597 | M24: ='Non Linear Calculation'!F23 -> 2.8100949 | N24: ='Non Linear Calculation'!G23 -> 7.0730071 | O24: ='Non Linear Calculation'!H23 -> 164.0597 | P24: ='Non Linear Calculation'!I23 -> 5.6910941 | ... R24: ='Non Linear Calculation'!K23 -> 2.0700861 | S24: {=SIGN(MMULT(I24:R24,'Non Linear Calculation'!$D$155:$D$164)-'Non Linear Calculation'!$E$155)} -> -1
A25: 8 | B25: =Input!G14 -> 0.59952058 | C25: =Input!H14 -> 0.48571836 | D25: =Input!I14 -> -1 | E25: =S25 -> -1 | F25: =IF(D25=E25,TRUE,FALSE) -> TRUE | H25: 8 | I25: ='Non Linear Calculation'!B24 -> 0.62995318 | J25: ='Non Linear Calculation'!C24 -> 1.7507786e-05 | K25: ='Non Linear Calculation'!D24 -> 1.0306066 | L25: ='Non Linear Calculation'!E24 -> 0.86865994 | M25: ='Non Linear Calculation'!F24 -> 1.917437 | N25: ='Non Linear Calculation'!G24 -> 4.4397718 | O25: ='Non Linear Calculation'!H24 -> 5.6910941 | P25: ='Non Linear Calculation'!I24 -> 6.4777012 | ... R25: ='Non Linear Calculation'!K24 -> 22.191202 | S25: {=SIGN(MMULT(I25:R25,'Non Linear Calculation'!$D$155:$D$164)-'Non Linear Calculation'!$E$155)} -> -1
A26: 9 | B26: =Input!G15 -> 0.11990412 | C26: =Input!H15 -> -0.32381224 | D26: =Input!I15 -> -1 | E26: =S26 -> -1 | F26: =IF(D26=E26,TRUE,FALSE) -> TRUE | H26: 9 | I26: ='Non Linear Calculation'!B25 -> 3.0923984 | J26: ='Non Linear Calculation'!C25 -> 1.2760616 | K26: ='Non Linear Calculation'!D25 -> 0.21819221 | L26: ='Non Linear Calculation'!E25 -> 6.2915778 | M26: ='Non Linear Calculation'!F25 -> 0.79571983 | N26: ='Non Linear Calculation'!G25 -> 0.61579996 | O26: ='Non Linear Calculation'!H25 -> 0.041032826 | P26: ='Non Linear Calculation'!I25 -> 0.69973131 | ... R26: ='Non Linear Calculation'!K25 -> 1.1238462 | S26: {=SIGN(MMULT(I26:R26,'Non Linear Calculation'!$D$155:$D$164)-'Non Linear Calculation'!$E$155)} -> -1
A27: 10 | B27: =Input!G16 -> 1.5587535 | C27: =Input!H16 -> 0.48571836 | D27: =Input!I16 -> -1 | E27: =S27 -> -1 | F27: =IF(D27=E27,TRUE,FALSE) -> TRUE | H27: 10 | I27: ='Non Linear Calculation'!B26 -> 46.842611 | J27: ='Non Linear Calculation'!C26 -> 0.88696653 | K27: ='Non Linear Calculation'!D26 -> 0.034985348 | L27: ='Non Linear Calculation'!E26 -> 16.017775 | M27: ='Non Linear Calculation'!F26 -> 2.7843322 | N27: ='Non Linear Calculation'!G26 -> 10.419094 | O27: ='Non Linear Calculation'!H26 -> 2.0700861 | P27: ='Non Linear Calculation'!I26 -> 22.191202 | ... R27: ='Non Linear Calculation'!K26 -> 180.5497 | S27: {=SIGN(MMULT(I27:R27,'Non Linear Calculation'!$D$155:$D$164)-'Non Linear Calculation'!$E$155)} -> -1
E36: x1 | F36: x2
E37: 1.5587535 | F37: 0.48571836
C41: Kx
C42: 1 | D42: {=(MMULT($E$37:$F$37,TRANSPOSE(B18:C18))+1)^4} -> 46.842611 | F42: Prediction | G42: {=SIGN(MMULT(TRANSPOSE(D42:D51),'Non Linear Calculation'!$D$155:$D$164)-'Non Linear Calculation'!$E$155)} -> -1
C43: 2 | D43: {=(MMULT($E$37:$F$37,TRANSPOSE(B19:C19))+1)^4} -> 0.88696653
C44: 3 | D44: {=(MMULT($E$37:$F$37,TRANSPOSE(B20:C20))+1)^4} -> 0.034985348
C45: 4 | D45: {=(MMULT($E$37:$F$37,TRANSPOSE(B21:C21))+1)^4} -> 16.017775
C46: 5 | D46: {=(MMULT($E$37:$F$37,TRANSPOSE(B22:C22))+1)^4} -> 2.7843322
C47: 6 | D47: {=(MMULT($E$37:$F$37,TRANSPOSE(B23:C23))+1)^4} -> 10.419094
C48: 7 | D48: {=(MMULT($E$37:$F$37,TRANSPOSE(B24:C24))+1)^4} -> 2.0700861
C49: 8 | D49: {=(MMULT($E$37:$F$37,TRANSPOSE(B25:C25))+1)^4} -> 22.191202
C50: 9 | D50: {=(MMULT($E$37:$F$37,TRANSPOSE(B26:C26))+1)^4} -> 1.1238462
C51: 10 | D51: {=(MMULT($E$37:$F$37,TRANSPOSE(B27:C27))+1)^4} -> 180.5497
A56: Grid Range -2 to +2
A60: =G42 -> -1 | B60: -2 | C60: -1.9 | D60: -1.8 | E60: -1.7 | F60: -1.6 | G60: -1.5 | H60: -1.4 | I60: -1.3 | J60: -1.2 | K60: -1.1 | L60: -1 | M60: -0.9 | N60: -0.8 | O60: -0.7 | P60: -0.6 | Q60: -0.5 | R60: -0.4 | S60: -0.3 | T60: -0.2 | U60: -0.1 | V60: 0 | W60: 0.1 | X60: 0.2 | Y60: 0.3 | Z60: 0.4 | AA60: 0.5 | AB60: 0.6 | AC60: 0.7 | AD60: 0.8 | AE60: 0.9 | AF60: 1 | AG60: 1.1 | AH60: 1.2 | AI60: 1.3 | AJ60: 1.4 | AK60: 1.5 | AL60: 1.6 | AM60: 1.7 | AN60: 1.8 | AO60: 1.9 | AP60: 2
A61: 2 | B61: 1 | C61: 1 | D61: 1 | E61: 1 | F61: 1 | G61: 1 | H61: 1 | I61: 1 | J61: 1 | K61: 1 | L61: 1 | M61: 1 | N61: -1 | O61: -1 | P61: -1 | Q61: -1 | R61: -1 | S61: -1 | T61: -1 | U61: -1 | V61: -1 | W61: -1 | X61: -1 | Y61: -1 | Z61: -1 | AA61: -1 | AB61: -1 | AC61: -1 | AD61: -1 | AE61: -1 | AF61: -1 | AG61: -1 | AH61: -1 | AI61: -1 | AJ61: -1 | AK61: -1 | AL61: -1 | AM61: -1 | AN61: -1 | AO61: -1 | AP61: -1
A62: 1.9 | B62: 1 | C62: 1 | D62: 1 | E62: 1 | F62: 1 | G62: 1 | H62: 1 | I62: 1 | J62: 1 | K62: 1 | L62: 1 | M62: 1 | N62: 1 | O62: -1 | P62: -1 | Q62: -1 | R62: -1 | S62: -1 | T62: -1 | U62: -1 | V62: -1 | W62: -1 | X62: -1 | Y62: -1 | Z62: -1 | AA62: -1 | AB62: -1 | AC62: -1 | AD62: -1 | AE62: -1 | AF62: -1 | AG62: -1 | AH62: -1 | AI62: -1 | AJ62: -1 | AK62: -1 | AL62: -1 | AM62: -1 | AN62: -1 | AO62: -1 | AP62: -1
A63: 1.8 | B63: 1 | C63: 1 | D63: 1 | E63: 1 | F63: 1 | G63: 1 | H63: 1 | I63: 1 | J63: 1 | K63: 1 | L63: 1 | M63: 1 | N63: 1 | O63: -1 | P63: -1 | Q63: -1 | R63: -1 | S63: -1 | T63: -1 | U63: -1 | V63: -1 | W63: -1 | X63: -1 | Y63: -1 | Z63: -1 | AA63: -1 | AB63: -1 | AC63: -1 | AD63: -1 | AE63: -1 | AF63: -1 | AG63: -1 | AH63: -1 | AI63: -1 | AJ63: -1 | AK63: -1 | AL63: -1 | AM63: -1 | AN63: -1 | AO63: -1 | AP63: -1
A64: 1.7 | B64: 1 | C64: 1 | D64: 1 | E64: 1 | F64: 1 | G64: 1 | H64: 1 | I64: 1 | J64: 1 | K64: 1 | L64: 1 | M64: 1 | N64: 1 | O64: 1 | P64: -1 | Q64: -1 | R64: -1 | S64: -1 | T64: -1 | U64: -1 | V64: -1 | W64: -1 | X64: -1 | Y64: -1 | Z64: -1 | AA64: -1 | AB64: -1 | AC64: -1 | AD64: -1 | AE64: -1 | AF64: -1 | AG64: -1 | AH64: -1 | AI64: -1 | AJ64: -1 | AK64: -1 | AL64: -1 | AM64: -1 | AN64: -1 | AO64: -1 | AP64: -1
A65: 1.6 | B65: 1 | C65: 1 | D65: 1 | E65: 1 | F65: 1 | G65: 1 | H65: 1 | I65: 1 | J65: 1 | K65: 1 | L65: 1 | M65: 1 | N65: 1 | O65: 1 | P65: 1 | Q65: -1 | R65: -1 | S65: -1 | T65: -1 | U65: -1 | V65: -1 | W65: -1 | X65: -1 | Y65: -1 | Z65: -1 | AA65: -1 | AB65: -1 | AC65: -1 | AD65: -1 | AE65: -1 | AF65: -1 | AG65: -1 | AH65: -1 | AI65: -1 | AJ65: -1 | AK65: -1 | AL65: -1 | AM65: -1 | AN65: -1 | AO65: -1 | AP65: -1
A66: 1.5 | B66: 1 | C66: 1 | D66: 1 | E66: 1 | F66: 1 | G66: 1 | H66: 1 | I66: 1 | J66: 1 | K66: 1 | L66: 1 | M66: 1 | N66: 1 | O66: 1 | P66: 1 | Q66: -1 | R66: -1 | S66: -1 | T66: -1 | U66: -1 | V66: -1 | W66: -1 | X66: -1 | Y66: -1 | Z66: -1 | AA66: -1 | AB66: -1 | AC66: -1 | AD66: -1 | AE66: -1 | AF66: -1 | AG66: -1 | AH66: -1 | AI66: -1 | AJ66: -1 | AK66: -1 | AL66: -1 | AM66: -1 | AN66: -1 | AO66: -1 | AP66: -1
A67: 1.4 | B67: 1 | C67: 1 | D67: 1 | E67: 1 | F67: 1 | G67: 1 | H67: 1 | I67: 1 | J67: 1 | K67: 1 | L67: 1 | M67: 1 | N67: 1 | O67: 1 | P67: 1 | Q67: 1 | R67: -1 | S67: -1 | T67: -1 | U67: -1 | V67: -1 | W67: -1 | X67: -1 | Y67: -1 | Z67: -1 | AA67: -1 | AB67: -1 | AC67: -1 | AD67: -1 | AE67: -1 | AF67: -1 | AG67: -1 | AH67: -1 | AI67: -1 | AJ67: -1 | AK67: -1 | AL67: -1 | AM67: -1 | AN67: -1 | AO67: -1 | AP67: -1
A68: 1.3 | B68: 1 | C68: 1 | D68: 1 | E68: 1 | F68: 1 | G68: 1 | H68: 1 | I68: 1 | J68: 1 | K68: 1 | L68: 1 | M68: 1 | N68: 1 | O68: 1 | P68: 1 | Q68: 1 | R68: -1 | S68: -1 | T68: -1 | U68: -1 | V68: -1 | W68: -1 | X68: -1 | Y68: -1 | Z68: -1 | AA68: -1 | AB68: -1 | AC68: -1 | AD68: -1 | AE68: -1 | AF68: -1 | AG68: -1 | AH68: -1 | AI68: -1 | AJ68: -1 | AK68: -1 | AL68: -1 | AM68: -1 | AN68: -1 | AO68: -1 | AP68: -1
A69: 1.2 | B69: 1 | C69: 1 | D69: 1 | E69: 1 | F69: 1 | G69: 1 | H69: 1 | I69: 1 | J69: 1 | K69: 1 | L69: 1 | M69: 1 | N69: 1 | O69: 1 | P69: 1 | Q69: 1 | R69: 1 | S69: -1 | T69: -1 | U69: -1 | V69: -1 | W69: -1 | X69: -1 | Y69: -1 | Z69: -1 | AA69: -1 | AB69: -1 | AC69: -1 | AD69: -1 | AE69: -1 | AF69: -1 | AG69: -1 | AH69: -1 | AI69: -1 | AJ69: -1 | AK69: -1 | AL69: -1 | AM69: -1 | AN69: -1 | AO69: -1 | AP69: -1
A70: 1.1 | B70: 1 | C70: 1 | D70: 1 | E70: 1 | F70: 1 | G70: 1 | H70: 1 | I70: 1 | J70: 1 | K70: 1 | L70: 1 | M70: 1 | N70: 1 | O70: 1 | P70: 1 | Q70: 1 | R70: 1 | S70: -1 | T70: -1 | U70: -1 | V70: -1 | W70: -1 | X70: -1 | Y70: -1 | Z70: -1 | AA70: -1 | AB70: -1 | AC70: -1 | AD70: -1 | AE70: -1 | AF70: -1 | AG70: -1 | AH70: -1 | AI70: -1 | AJ70: -1 | AK70: -1 | AL70: -1 | AM70: -1 | AN70: -1 | AO70: -1 | AP70: -1
A71: 1 | B71: 1 | C71: 1 | D71: 1 | E71: 1 | F71: 1 | G71: 1 | H71: 1 | I71: 1 | J71: 1 | K71: 1 | L71: 1 | M71: 1 | N71: 1 | O71: 1 | P71: 1 | Q71: 1 | R71: 1 | S71: 1 | T71: -1 | U71: -1 | V71: -1 | W71: -1 | X71: -1 | Y71: -1 | Z71: -1 | AA71: -1 | AB71: -1 | AC71: -1 | AD71: -1 | AE71: -1 | AF71: -1 | AG71: -1 | AH71: -1 | AI71: -1 | AJ71: -1 | AK71: -1 | AL71: -1 | AM71: -1 | AN71: -1 | AO71: -1 | AP71: -1
A72: 0.9 | B72: 1 | C72: 1 | D72: 1 | E72: 1 | F72: 1 | G72: 1 | H72: 1 | I72: 1 | J72: 1 | K72: 1 | L72: 1 | M72: 1 | N72: 1 | O72: 1 | P72: 1 | Q72: 1 | R72: 1 | S72: 1 | T72: -1 | U72: -1 | V72: -1 | W72: -1 | X72: -1 | Y72: -1 | Z72: -1 | AA72: -1 | AB72: -1 | AC72: -1 | AD72: -1 | AE72: -1 | AF72: -1 | AG72: -1 | AH72: -1 | AI72: -1 | AJ72: -1 | AK72: -1 | AL72: -1 | AM72: -1 | AN72: -1 | AO72: -1 | AP72: -1
...

Sheet Plotting
A1: ='Non Linear Prediction'!B61 -> 1 | B1: ='Non Linear Prediction'!C61 -> 1 | C1: ='Non Linear Prediction'!D61 -> 1 | D1: ='Non Linear Prediction'!E61 -> 1 | E1: ='Non Linear Prediction'!F61 -> 1 | F1: ='Non Linear Prediction'!G61 -> 1 | G1: ='Non Linear Prediction'!H61 -> 1 | H1: ='Non Linear Prediction'!I61 -> 1 | ... AO1: ='Non Linear Prediction'!AP61 -> -1
A2: ='Non Linear Prediction'!B62 -> 1 | B2: ='Non Linear Prediction'!C62 -> 1 | C2: ='Non Linear Prediction'!D62 -> 1 | D2: ='Non Linear Prediction'!E62 -> 1 | E2: ='Non Linear Prediction'!F62 -> 1 | F2: ='Non Linear Prediction'!G62 -> 1 | G2: ='Non Linear Prediction'!H62 -> 1 | H2: ='Non Linear Prediction'!I62 -> 1 | ... AO2: ='Non Linear Prediction'!AP62 -> -1
A3: ='Non Linear Prediction'!B63 -> 1 | B3: ='Non Linear Prediction'!C63 -> 1 | C3: ='Non Linear Prediction'!D63 -> 1 | D3: ='Non Linear Prediction'!E63 -> 1 | E3: ='Non Linear Prediction'!F63 -> 1 | F3: ='Non Linear Prediction'!G63 -> 1 | G3: ='Non Linear Prediction'!H63 -> 1 | H3: ='Non Linear Prediction'!I63 -> 1 | ... AO3: ='Non Linear Prediction'!AP63 -> -1
A4: ='Non Linear Prediction'!B64 -> 1 | B4: ='Non Linear Prediction'!C64 -> 1 | C4: ='Non Linear Prediction'!D64 -> 1 | D4: ='Non Linear Prediction'!E64 -> 1 | E4: ='Non Linear Prediction'!F64 -> 1 | F4: ='Non Linear Prediction'!G64 -> 1 | G4: ='Non Linear Prediction'!H64 -> 1 | H4: ='Non Linear Prediction'!I64 -> 1 | ... AO4: ='Non Linear Prediction'!AP64 -> -1
A5: ='Non Linear Prediction'!B65 -> 1 | B5: ='Non Linear Prediction'!C65 -> 1 | C5: ='Non Linear Prediction'!D65 -> 1 | D5: ='Non Linear Prediction'!E65 -> 1 | E5: ='Non Linear Prediction'!F65 -> 1 | F5: ='Non Linear Prediction'!G65 -> 1 | G5: ='Non Linear Prediction'!H65 -> 1 | H5: ='Non Linear Prediction'!I65 -> 1 | ... AO5: ='Non Linear Prediction'!AP65 -> -1
A6: ='Non Linear Prediction'!B66 -> 1 | B6: ='Non Linear Prediction'!C66 -> 1 | C6: ='Non Linear Prediction'!D66 -> 1 | D6: ='Non Linear Prediction'!E66 -> 1 | E6: ='Non Linear Prediction'!F66 -> 1 | F6: ='Non Linear Prediction'!G66 -> 1 | G6: ='Non Linear Prediction'!H66 -> 1 | H6: ='Non Linear Prediction'!I66 -> 1 | ... AO6: ='Non Linear Prediction'!AP66 -> -1
A7: ='Non Linear Prediction'!B67 -> 1 | B7: ='Non Linear Prediction'!C67 -> 1 | C7: ='Non Linear Prediction'!D67 -> 1 | D7: ='Non Linear Prediction'!E67 -> 1 | E7: ='Non Linear Prediction'!F67 -> 1 | F7: ='Non Linear Prediction'!G67 -> 1 | G7: ='Non Linear Prediction'!H67 -> 1 | H7: ='Non Linear Prediction'!I67 -> 1 | ... AO7: ='Non Linear Prediction'!AP67 -> -1
A8: ='Non Linear Prediction'!B68 -> 1 | B8: ='Non Linear Prediction'!C68 -> 1 | C8: ='Non Linear Prediction'!D68 -> 1 | D8: ='Non Linear Prediction'!E68 -> 1 | E8: ='Non Linear Prediction'!F68 -> 1 | F8: ='Non Linear Prediction'!G68 -> 1 | G8: ='Non Linear Prediction'!H68 -> 1 | H8: ='Non Linear Prediction'!I68 -> 1 | ... AO8: ='Non Linear Prediction'!AP68 -> -1
A9: ='Non Linear Prediction'!B69 -> 1 | B9: ='Non Linear Prediction'!C69 -> 1 | C9: ='Non Linear Prediction'!D69 -> 1 | D9: ='Non Linear Prediction'!E69 -> 1 | E9: ='Non Linear Prediction'!F69 -> 1 | F9: ='Non Linear Prediction'!G69 -> 1 | G9: ='Non Linear Prediction'!H69 -> 1 | H9: ='Non Linear Prediction'!I69 -> 1 | ... AO9: ='Non Linear Prediction'!AP69 -> -1
A10: ='Non Linear Prediction'!B70 -> 1 | B10: ='Non Linear Prediction'!C70 -> 1 | C10: ='Non Linear Prediction'!D70 -> 1 | D10: ='Non Linear Prediction'!E70 -> 1 | E10: ='Non Linear Prediction'!F70 -> 1 | F10: ='Non Linear Prediction'!G70 -> 1 | G10: ='Non Linear Prediction'!H70 -> 1 | H10: ='Non Linear Prediction'!I70 -> 1 | ... AO10: ='Non Linear Prediction'!AP70 -> -1
A11: ='Non Linear Prediction'!B71 -> 1 | B11: ='Non Linear Prediction'!C71 -> 1 | C11: ='Non Linear Prediction'!D71 -> 1 | D11: ='Non Linear Prediction'!E71 -> 1 | E11: ='Non Linear Prediction'!F71 -> 1 | F11: ='Non Linear Prediction'!G71 -> 1 | G11: ='Non Linear Prediction'!H71 -> 1 | H11: ='Non Linear Prediction'!I71 -> 1 | ... AO11: ='Non Linear Prediction'!AP71 -> -1
A12: ='Non Linear Prediction'!B72 -> 1 | B12: ='Non Linear Prediction'!C72 -> 1 | C12: ='Non Linear Prediction'!D72 -> 1 | D12: ='Non Linear Prediction'!E72 -> 1 | E12: ='Non Linear Prediction'!F72 -> 1 | F12: ='Non Linear Prediction'!G72 -> 1 | G12: ='Non Linear Prediction'!H72 -> 1 | H12: ='Non Linear Prediction'!I72 -> 1 | ... AO12: ='Non Linear Prediction'!AP72 -> -1
... A41: ='Non Linear Prediction'!B101 -> 1 | B41: ='Non Linear Prediction'!C101 -> -1 | C41: ='Non Linear Prediction'!D101 -> -1 | D41: ='Non Linear Prediction'!E101 -> -1 | E41: ='Non Linear Prediction'!F101 -> -1 | F41: ='Non Linear Prediction'!G101 -> -1 | G41: ='Non Linear Prediction'!H101 -> -1 | H41: ='Non Linear Prediction'!I101 -> -1 | ... AO41: ='Non Linear Prediction'!AP101 -> 1
