Workbook

Sheet Input
A2: Linear PSVM Problem
A5: Input Data Points | F5: Normalized Data Points
A6: INDEX | B6: X1 | C6: X2 | D6: CLASS | F6: INDEX | G6: X1 | H6: X2 | I6: CLASS
A7: 1 | B7: 0 | C7: 0 | D7: 1 | F7: =A7 -> 1 | G7: =(B7-B$17)/B$18 -> -1.7985617 | H7: =(C7-C$17)/C$18 -> -1.6730299 | I7: =D7 -> 1
A8: 2 | B8: 3 | C8: 4 | D8: 1 | F8: =A8 -> 2 | G8: =(B8-B$17)/B$18 -> -1.079137 | H8: =(C8-C$17)/C$18 -> -0.59365578 | I8: =D8 -> 1
A9: 3 | B9: 5 | C9: 9 | D9: 1 | F9: =A9 -> 3 | G9: =(B9-B$17)/B$18 -> -0.59952058 | H9: =(C9-C$17)/C$18 -> 0.7555619 | I9: =D9 -> 1
A10: 4 | B10: 12 | C10: 1 | D10: 1 | F10: =A10 -> 4 | G10: =(B10-B$17)/B$18 -> 1.079137 | H10: =(C10-C$17)/C$18 -> -1.4031864 | I10: =D10 -> 1
A11: 5 | B11: 8 | C11: 7 | D11: 1 | F11: =A11 -> 5 | G11: =(B11-B$17)/B$18 -> 0.11990412 | H11: =(C11-C$17)/C$18 -> 0.21587483 | I11: =D11 -> 1
A12: 6 | B12: 9 | C12: 8 | D12: -1 | F12: =A12 -> 6 | G12: =(B12-B$17)/B$18 -> 0.35971235 | H12: =(C12-C$17)/C$18 -> 0.48571836 | I12: =D12 -> -1
A13: 7 | B13: 6 | C13: 12 | D13: -1 | F13: =A13 -> 7 | G13: =(B13-B$17)/B$18 -> -0.35971235 | H13: =(C13-C$17)/C$18 -> 1.5650925 | I13: =D13 -> -1
A14: 8 | B14: 10 | C14: 8 | D14: -1 | F14: =A14 -> 8 | G14: =(B14-B$17)/B$18 -> 0.59952058 | H14: =(C14-C$17)/C$18 -> 0.48571836 | I14: =D14 -> -1
A15: 9 | B15: 8 | C15: 5 | D15: -1 | F15: =A15 -> 9 | G15: =(B15-B$17)/B$18 -> 0.11990412 | H15: =(C15-C$17)/C$18 -> -0.32381224 | I15: =D15 -> -1
A16: 10 | B16: 14 | C16: 8 | D16: -1 | F16: =A16 -> 10 | G16: =(B16-B$17)/B$18 -> 1.5587535 | H16: =(C16-C$17)/C$18 -> 0.48571836 | I16: =D16 -> -1
A17: Mean | B17: =AVERAGE(B7:B16) -> 7.5 | C17: =AVERAGE(C7:C16) -> 6.2
A18: SD | B18: =STDEV(B7:B16) -> 4.1699987 | C18: =STDEV(C7:C16) -> 3.7058512

Sheet Linear Calculation
A2: Calculation using PSVM
A5: Augmented Matrix (A-e)
A6: =Input!G7 -> -1.7985617 | B6: =Input!H7 -> -1.6730299 | C6: -1
A7: =Input!G8 -> -1.079137 | B7: =Input!H8 -> -0.59365578 | C7: -1
A8: =Input!G9 -> -0.59952058 | B8: =Input!H9 -> 0.7555619 | C8: -1
A9: =Input!G10 -> 1.079137 | B9: =Input!H10 -> -1.4031864 | C9: -1
A10: =Input!G11 -> 0.11990412 | B10: =Input!H11 -> 0.21587483 | C10: -1
A11: =Input!G12 -> 0.35971235 | B11: =Input!H12 -> 0.48571836 | C11: -1
A12: =Input!G13 -> -0.35971235 | B12: =Input!H13 -> 1.5650925 | C12: -1
A13: =Input!G14 -> 0.59952058 | B13: =Input!H14 -> 0.48571836 | C13: -1
A14: =Input!G15 -> 0.11990412 | B14: =Input!H15 -> -0.32381224 | C14: -1
A15: =Input!G16 -> 1.5587535 | B15: =Input!H16 -> 0.48571836 | C15: -1
B19: x1 | C19: x2 | D19: D
A20: index | B20: 8 | C20: 8 | D20: =IF($B$20=$C$20,INDEX(Input!$D$7:$D$16,$B$20,1),0) -> -1
A22: Diagonal Matrix D having Class values
A23: =D20 -> -1 | B23: 1 | C23: 2 | D23: 3 | E23: 4 | F23: 5 | G23: 6 | H23: 7 | I23: 8 | J23: 9 | K23: 10
A24: 1 | B24: 1 | C24: 0 | D24: 0 | E24: 0 | F24: 0 | G24: 0 | H24: 0 | I24: 0 | J24: 0 | K24: 0
A25: 2 | B25: 0 | C25: 1 | D25: 0 | E25: 0 | F25: 0 | G25: 0 | H25: 0 | I25: 0 | J25: 0 | K25: 0
A26: 3 | B26: 0 | C26: 0 | D26: 1 | E26: 0 | F26: 0 | G26: 0 | H26: 0 | I26: 0 | J26: 0 | K26: 0
A27: 4 | B27: 0 | C27: 0 | D27: 0 | E27: 1 | F27: 0 | G27: 0 | H27: 0 | I27: 0 | J27: 0 | K27: 0
A28: 5 | B28: 0 | C28: 0 | D28: 0 | E28: 0 | F28: 1 | G28: 0 | H28: 0 | I28: 0 | J28: 0 | K28: 0
A29: 6 | B29: 0 | C29: 0 | D29: 0 | E29: 0 | F29: 0 | G29: -1 | H29: 0 | I29: 0 | J29: 0 | K29: 0
A30: 7 | B30: 0 | C30: 0 | D30: 0 | E30: 0 | F30: 0 | G30: 0 | H30: -1 | I30: 0 | J30: 0 | K30: 0
A31: 8 | B31: 0 | C31: 0 | D31: 0 | E31: 0 | F31: 0 | G31: 0 | H31: 0 | I31: -1 | J31: 0 | K31: 0
A32: 9 | B32: 0 | C32: 0 | D32: 0 | E32: 0 | F32: 0 | G32: 0 | H32: 0 | I32: 0 | J32: -1 | K32: 0
A33: 10 | B33: 0 | C33: 0 | D33: 0 | E33: 0 | F33: 0 | G33: 0 | H33: 0 | I33: 0 | J33: 0 | K33: -1
A38: H
A39: {=MMULT(B24:K33,A6:C15)} -> -1.7985617 | B39: -1.6730299 | C39: -1
A40: -1.079137 | B40: -0.59365578 | C40: -1
A41: -0.59952058 | B41: 0.7555619 | C41: -1
A42: 1.079137 | B42: -1.4031864 | C42: -1
A43: 0.11990412 | B43: 0.21587483 | C43: -1
A44: -0.35971235 | B44: -0.48571836 | C44: 1
A45: 0.35971235 | B45: -1.5650925 | C45: 1
A46: -0.59952058 | B46: -0.48571836 | C46: 1
A47: -0.11990412 | B47: 0.32381224 | C47: 1
A48: -1.5587535 | B48: -0.48571836 | C48: 1
A51: HTH
A52: {=MMULT(TRANSPOSE(A39:C48),A39:C48)} -> 9 | B52: 2.3295852 | C52: 0
A53: 2.3295852 | B53: 9 | C53: 2.7755576e-16
...

Sheet Linear Prediction
A2: PREDICTION FUNCTION
A6: Prediction to training data
A7: INDEX | B7: X1 | C7: X2 | D7: Actual CLASS | E7: Predicted
A8: 1 | B8: -1.7985617 | C8: -1.6730299 | D8: 1 | E8: {=SIGN(MMULT(TRANSPOSE('Linear Calculation'!$D$109:$D$110),TRANSPOSE(B8:C8))-'Linear Calculation'!$E$109)} -> 1
A9: 2 | B9: -1.079137 | C9: -0.59365578 | D9: 1 | E9: {=SIGN(MMULT(TRANSPOSE('Linear Calculation'!$D$109:$D$110),TRANSPOSE(B9:C9))-'Linear Calculation'!$E$109)} -> 1
A10: 3 | B10: -0.59952058 | C10: 0.7555619 | D10: 1 | E10: {=SIGN(MMULT(TRANSPOSE('Linear Calculation'!$D$109:$D$110),TRANSPOSE(B10:C10))-'Linear Calculation'!$E$109)} -> -1
A11: 4 | B11: 1.079137 | C11: -1.4031864 | D11: 1 | E11: {=SIGN(MMULT(TRANSPOSE('Linear Calculation'!$D$109:$D$110),TRANSPOSE(B11:C11))-'Linear Calculation'!$E$109)} -> 1
A12: 5 | B12: 0.11990412 | C12: 0.21587483 | D12: 1 | E12: {=SIGN(MMULT(TRANSPOSE('Linear Calculation'!$D$109:$D$110),TRANSPOSE(B12:C12))-'Linear Calculation'!$E$109)} -> -1
A13: 6 | B13: 0.35971235 | C13: 0.48571836 | D13: -1 | E13: {=SIGN(MMULT(TRANSPOSE('Linear Calculation'!$D$109:$D$110),TRANSPOSE(B13:C13))-'Linear Calculation'!$E$109)} -> -1
A14: 7 | B14: -0.35971235 | C14: 1.5650925 | D14: -1 | E14: {=SIGN(MMULT(TRANSPOSE('Linear Calculation'!$D$109:$D$110),TRANSPOSE(B14:C14))-'Linear Calculation'!$E$109)} -> -1
A15: 8 | B15: 0.59952058 | C15: 0.48571836 | D15: -1 | E15: {=SIGN(MMULT(TRANSPOSE('Linear Calculation'!$D$109:$D$110),TRANSPOSE(B15:C15))-'Linear Calculation'!$E$109)} -> -1
A16: 9 | B16: 0.11990412 | C16: -0.32381224 | D16: -1 | E16: {=SIGN(MMULT(TRANSPOSE('Linear Calculation'!$D$109:$D$110),TRANSPOSE(B16:C16))-'Linear Calculation'!$E$109)} -> 1
A17: 10 | B17: 1.5587535 | C17: 0.48571836 | D17: -1 | E17: {=SIGN(MMULT(TRANSPOSE('Linear Calculation'!$D$109:$D$110),TRANSPOSE(B17:C17))-'Linear Calculation'!$E$109)} -> -1 | F17: 70% accuracy
C21: x | D21: y | E21: Response
B22: index | C22: 1 | D22: 1 | E22: {=SIGN(MMULT(TRANSPOSE('Linear Calculation'!$D$109:$D$110),TRANSPOSE(C22:D22))-'Linear Calculation'!$E$109)} -> -1
A24: =E22 -> -1 | B24: -2 | C24: -1.99 | D24: -1.98 | E24: -1.97 | F24: -1.96 | G24: -1.95 | H24: -1.94 | I24: -1.93 | J24: -1.92 | K24: -1.91 | L24: -1.9 | M24: -1.89 | N24: -1.88 | O24: -1.87 | P24: -1.86 | Q24: -1.85 | R24: -1.84 | S24: -1.83 | T24: -1.82 | U24: -1.81 | V24: -1.8 | W24: -1.79 | X24: -1.78 | Y24: -1.77 | Z24: -1.76 | AA24: -1.75 | AB24: -1.74 | AC24: -1.73 | AD24: -1.72 | AE24: -1.71 | AF24: -1.7 | AG24: -1.69 | AH24: -1.68 | AI24: -1.67 | AJ24: -1.66 | AK24: -1.65 | AL24: -1.64 | AM24: -1.63 | AN24: -1.62 | AO24: -1.61 | AP24: -1.6 | AQ24: -1.59 | AR24: -1.58 | AS24: -1.57 | AT24: -1.56 | AU24: -1.55 | AV24: -1.54 | AW24: -1.53 | AX24: -1.52 | AY24: -1.51 | AZ24: -1.5 | BA24: -1.49 | BB24: -1.48 | BC24: -1.47 | BD24: -1.46 | BE24: -1.45 | BF24: -1.44 | BG24: -1.43 | BH24: -1.42 | BI24: -1.41 | BJ24: -1.4 | BK24: -1.39 | BL24: -1.38 | BM24: -1.37 | BN24: -1.36 | BO24: -1.35 | BP24: -1.34 | BQ24: -1.33 | BR24: -1.32 | BS24: -1.31 | BT24: -1.3 | BU24: -1.29 | BV24: -1.28 | BW24: -1.27 | BX24: -1.26 | BY24: -1.25 | BZ24: -1.24 | CA24: -1.23 | CB24: -1.22 | CC24: -1.21 | CD24: -1.2 | CE24: -1.19 | CF24: -1.18 | CG24: -1.17 | CH24: -1.16 | CI24: -1.15 | CJ24: -1.14 | CK24: -1.13 | CL24: -1.12 | CM24: -1.11 | CN24: -1.1 | CO24: -1.09 | CP24: -1.08 | CQ24: -1.07 | CR24: -1.06 | CS24: -1.05 | CT24: -1.04 | CU24: -1.03 | CV24: -1.02 | CW24: -1.01 | CX24: -1 | CY24: -0.99 | CZ24: -0.98 | DA24: -0.97 | DB24: -0.96 | DC24: -0.95 | DD24: -0.94 | DE24: -0.93 | DF24: -0.92 | DG24: -0.91 | DH24: -0.9 | DI24: -0.89 | DJ24: -0.88 | DK24: -0.87 | DL24: -0.86 | DM24: -0.85 | DN24: -0.84 | DO24: -0.83 | DP24: -0.82 | DQ24: -0.81 | DR24: -0.8 | DS24: -0.79 | DT24: -0.78 | DU24: -0.77 | DV24: -0.76 | DW24: -0.75 | DX24: -0.74 | DY24: -0.73 | DZ24: -0.72 | EA24: -0.71 | EB24: -0.7 | EC24: -0.69 | ED24: -0.68 | EE24: -0.67 | EF24: -0.66 | EG24: -0.65 | EH24: -0.64 | EI24: -0.63 | EJ24: -0.62 | EK24: -0.61 | EL24: -0.6 | EM24: -0.59 | EN24: -0.58 | EO24: -0.57 | EP24: -0.56 | EQ24: -0.55 | ER24: -0.54 | ES24: -0.53 | ET24: -0.52 | EU24: -0.51 | EV24: -0.5 | EW24: -0.49 | EX24: -0.48 | EY24: -0.47 | EZ24: -0.46 | FA24: -0.45 | FB24: -0.44 | FC24: -0.43 | FD24: -0.42 | FE24: -0.41 | FF24: -0.4 | FG24: -0.39 | FH24: -0.38 | FI24: -0.37 | FJ24: -0.36 | FK24: -0.35 | FL24: -0.34 | FM24: -0.33 | FN24: -0.32 | FO24: -0.31 | FP24: -0.3 | FQ24: -0.29 | FR24: -0.28 | FS24: -0.27 | FT24: -0.26 | FU24: -0.25 | FV24: -0.24 | FW24: -0.23 | FX24: -0.22 | FY24: -0.21 | FZ24: -0.2 | GA24: -0.19 | GB24: -0.18 | GC24: -0.17 | GD24: -0.16 | GE24: -0.15 | GF24: -0.14 | GG24: -0.13 | GH24: -0.12 | GI24: -0.11 | GJ24: -0.1 | GK24: -0.09 | GL24: -0.08 | GM24: -0.07 | GN24: -0.06 | GO24: -0.05 | GP24: -0.04 | GQ24: -0.03 | GR24: -0.02 | GS24: -0.01 | GT24: 0 | GU24: 0.01 | GV24: 0.02 | GW24: 0.03 | GX24: 0.04 | GY24: 0.05 | GZ24: 0.06 | HA24: 0.07 | HB24: 0.08 | HC24: 0.09 | HD24: 0.1 | HE24: 0.11 | HF24: 0.12 | HG24: 0.13 | HH24: 0.14 | HI24: 0.15 | HJ24: 0.16 | HK24: 0.17 | HL24: 0.18 | HM24: 0.19 | HN24: 0.2 | HO24: 0.21 | HP24: 0.22 | HQ24: 0.23 | HR24: 0.24 | HS24: 0.25 | HT24: 0.26 | HU24: 0.27 | HV24: 0.28 | HW24: 0.29 | HX24: 0.3 | HY24: 0.31 | HZ24: 0.32 | IA24: 0.33 | IB24: 0.34 | IC24: 0.35 | ID24: 0.36 | IE24: 0.37 | IF24: 0.38 | IG24: 0.39 | IH24: 0.4 | II24: 0.41 | IJ24: 0.42 | IK24: 0.43 | IL24: 0.44 | IM24: 0.45 | IN24: 0.46 | IO24: 0.47 | IP24: 0.48 | IQ24: 0.49 | IR24: 0.5 | IS24: 0.51 | IT24: 0.52 | IU24: 0.53 | IV24: 0.54 | IW24: 0.55 | IX24: 0.56 | IY24: 0.57 | IZ24: 0.58 | JA24: 0.59 | JB24: 0.6 | JC24: 0.61 | JD24: 0.62 | JE24: 0.63 | JF24: 0.64 | JG24: 0.65 | JH24: 0.66 | JI24: 0.67 | JJ24: 0.68 | JK24: 0.69 | JL24: 0.7 | JM24: 0.71 | JN24: 0.72 | JO24: 0.73 | JP24: 0.74 | JQ24: 0.75 | JR24: 0.76 | JS24: 0.77 | JT24: 0.78 | JU24: 0.79 | JV24: 0.8 | JW24: 0.81 | JX24: 0.82 | JY24: 0.83 | JZ24: 0.84 | KA24: 0.85 | KB24: 0.86 | KC24: 0.87 | KD24: 0.88 | KE24: 0.89 | KF24: 0.9 | KG24: 0.91 | KH24: 0.92 | KI24: 0.93 | KJ24: 0.94 | KK24: 0.95 | KL24: 0.96 | KM24: 0.97 | KN24: 0.98 | KO24: 0.99 | KP24: 1 | KQ24: 1.01 | KR24: 1.02 | KS24: 1.03 | KT24: 1.04 | KU24: 1.05 | KV24: 1.06 | KW24: 1.07 | KX24: 1.08 | KY24: 1.09 | KZ24: 1.1 | LA24: 1.11 | LB24: 1.12 | LC24: 1.13 | LD24: 1.14 | LE24: 1.15 | LF24: 1.16 | LG24: 1.17 | LH24: 1.18 | LI24: 1.19 | LJ24: 1.2 | LK24: 1.21 | LL24: 1.22 | LM24: 1.23 | LN24: 1.24 | LO24: 1.25 | LP24: 1.26 | LQ24: 1.27 | LR24: 1.28 | LS24: 1.29 | LT24: 1.3 | LU24: 1.31 | LV24: 1.32 | LW24: 1.33 | LX24: 1.34 | LY24: 1.35 | LZ24: 1.36 | MA24: 1.37 | MB24: 1.38 | MC24: 1.39 | MD24: 1.4 | ME24: 1.41 | MF24: 1.42 | MG24: 1.43 | MH24: 1.44 | MI24: 1.45 | MJ24: 1.46 | MK24: 1.47 | ML24: 1.48 | MM24: 1.49 | MN24: 1.5 | MO24: 1.51 | MP24: 1.52 | MQ24: 1.53 | MR24: 1.54 | MS24: 1.55 | MT24: 1.56 | MU24: 1.57 | MV24: 1.58 | MW24: 1.59 | MX24: 1.6 | MY24: 1.61 | MZ24: 1.62 | NA24: 1.63 | NB24: 1.64 | NC24: 1.65 | ND24: 1.66 | NE24: 1.67 | NF24: 1.68 | NG24: 1.69 | NH24: 1.7 | NI24: 1.71 | NJ24: 1.72 | NK24: 1.73 | NL24: 1.74 | NM24: 1.75 | NN24: 1.76 | NO24: 1.77 | NP24: 1.78 | NQ24: 1.79 | NR24: 1.8 | NS24: 1.81 | NT24: 1.82 | NU24: 1.83 | NV24: 1.84 | NW24: 1.85 | NX24: 1.86 | NY24: 1.87 | NZ24: 1.88 | OA24: 1.89 | OB24: 1.9 | OC24: 1.91 | OD24: 1.92 | OE24: 1.93 | OF24: 1.94 | OG24: 1.95 | OH24: 1.96 | OI24: 1.97 | OJ24: 1.98 | OK24: 1.99 | OL24: 2
A25: 2 | B25: -1 | C25: -1 | D25: -1 | E25: -1 | F25: -1 | G25: -1 | H25: -1 | I25: -1 | J25: -1 | K25: -1 | L25: -1 | M25: -1 | N25: -1 | O25: -1 | P25: -1 | Q25: -1 | R25: -1 | S25: -1 | T25: -1 | U25: -1 | V25: -1 | W25: -1 | X25: -1 | Y25: -1 | Z25: -1 | AA25: -1 | AB25: -1 | AC25: -1 | AD25: -1 | AE25: -1 | AF25: -1 | AG25: -1 | AH25: -1 | AI25: -1 | AJ25: -1 | AK25: -1 | AL25: -1 | AM25: -1 | AN25: -1 | AO25: -1 | AP25: -1 | AQ25: -1 | AR25: -1 | AS25: -1 | AT25: -1 | AU25: -1 | AV25: -1 | AW25: -1 | AX25: -1 | AY25: -1 | AZ25: -1 | BA25: -1 | BB25: -1 | BC25: -1 | BD25: -1 | BE25: -1 | BF25: -1 | BG25: -1 | BH25: -1 | BI25: -1 | BJ25: -1 | BK25: -1 | BL25: -1 | BM25: -1 | BN25: -1 | BO25: -1 | BP25: -1 | BQ25: -1 | BR25: -1 | BS25: -1 | BT25: -1 | BU25: -1 | BV25: -1 | BW25: -1 | BX25: -1 | BY25: -1 | BZ25: -1 | CA25: -1 | CB25: -1 | CC25: -1 | CD25: -1 | CE25: -1 | CF25: -1 | CG25: -1 | CH25: -1 | CI25: -1 | CJ25: -1 | CK25: -1 | CL25: -1 | CM25: -1 | CN25: -1 | CO25: -1 | CP25: -1 | CQ25: -1 | CR25: -1 | CS25: -1 | CT25: -1 | CU25: -1 | CV25: -1 | CW25: -1 | CX25: -1 | CY25: -1 | CZ25: -1 | DA25: -1 | DB25: -1 | DC25: -1 | DD25: -1 | DE25: -1 | DF25: -1 | DG25: -1 | DH25: -1 | DI25: -1 | DJ25: -1 | DK25: -1 | DL25: -1 | DM25: -1 | DN25: -1 | DO25: -1 | DP25: -1 | DQ25: -1 | DR25: -1 | DS25: -1 | DT25: -1 | DU25: -1 | DV25: -1 | DW25: -1 | DX25: -1 | DY25: -1 | DZ25: -1 | EA25: -1 | EB25: -1 | EC25: -1 | ED25: -1 | EE25: -1 | EF25: -1 | EG25: -1 | EH25: -1 | EI25: -1 | EJ25: -1 | EK25: -1 | EL25: -1 | EM25: -1 | EN25: -1 | EO25: -1 | EP25: -1 | EQ25: -1 | ER25: -1 | ES25: -1 | ET25: -1 | EU25: -1 | EV25: -1 | EW25: -1 | EX25: -1 | EY25: -1 | EZ25: -1 | FA25: -1 | FB25: -1 | FC25: -1 | FD25: -1 | FE25: -1 | FF25: -1 | FG25: -1 | FH25: -1 | FI25: -1 | FJ25: -1 | FK25: -1 | FL25: -1 | FM25: -1 | FN25: -1 | FO25: -1 | FP25: -1 | FQ25: -1 | FR25: -1 | FS25: -1 | FT25: -1 | FU25: -1 | FV25: -1 | FW25: -1 | FX25: -1 | FY25: -1 | FZ25: -1 | GA25: -1 | GB25: -1 | GC25: -1 | GD25: -1 | GE25: -1 | GF25: -1 | GG25: -1 | GH25: -1 | GI25: -1 | GJ25: -1 | GK25: -1 | GL25: -1 | GM25: -1 | GN25: -1 | GO25: -1 | GP25: -1 | GQ25: -1 | GR25: -1 | GS25: -1 | GT25: -1 | GU25: -1 | GV25: -1 | GW25: -1 | GX25: -1 | GY25: -1 | GZ25: -1 | HA25: -1 | HB25: -1 | HC25: -1 | HD25: -1 | HE25: -1 | HF25: -1 | HG25: -1 | HH25: -1 | HI25: -1 | HJ25: -1 | HK25: -1 | HL25: -1 | HM25: -1 | HN25: -1 | HO25: -1 | HP25: -1 | HQ25: -1 | HR25: -1 | HS25: -1 | HT25: -1 | HU25: -1 | HV25: -1 | HW25: -1 | HX25: -1 | HY25: -1 | HZ25: -1 | IA25: -1 | IB25: -1 | IC25: -1 | ID25: -1 | IE25: -1 | IF25: -1 | IG25: -1 | IH25: -1 | II25: -1 | IJ25: -1 | IK25: -1 | IL25: -1 | IM25: -1 | IN25: -1 | IO25: -1 | IP25: -1 | IQ25: -1 | IR25: -1 | IS25: -1 | IT25: -1 | IU25: -1 | IV25: -1 | IW25: -1 | IX25: -1 | IY25: -1 | IZ25: -1 | JA25: -1 | JB25: -1 | JC25: -1 | JD25: -1 | JE25: -1 | JF25: -1 | JG25: -1 | JH25: -1 | JI25: -1 | JJ25: -1 | JK25: -1 | JL25: -1 | JM25: -1 | JN25: -1 | JO25: -1 | JP25: -1 | JQ25: -1 | JR25: -1 | JS25: -1 | JT25: -1 | JU25: -1 | JV25: -1 | JW25: -1 | JX25: -1 | JY25: -1 | JZ25: -1 | KA25: -1 | KB25: -1 | KC25: -1 | KD25: -1 | KE25: -1 | KF25: -1 | KG25: -1 | KH25: -1 | KI25: -1 | KJ25: -1 | KK25: -1 | KL25: -1 | KM25: -1 | KN25: -1 | KO25: -1 | KP25: -1 | KQ25: -1 | KR25: -1 | KS25: -1 | KT25: -1 | KU25: -1 | KV25: -1 | KW25: -1 | KX25: -1 | KY25: -1 | KZ25: -1 | LA25: -1 | LB25: -1 | LC25: -1 | LD25: -1 | LE25: -1 | LF25: -1 | LG25: -1 | LH25: -1 | LI25: -1 | LJ25: -1 | LK25: -1 | LL25: -1 | LM25: -1 | LN25: -1 | LO25: -1 | LP25: -1 | LQ25: -1 | LR25: -1 | LS25: -1 | LT25: -1 | LU25: -1 | LV25: -1 | LW25: -1 | LX25: -1 | LY25: -1 | LZ25: -1 | MA25: -1 | MB25: -1 | MC25: -1 | MD25: -1 | ME25: -1 | MF25: -1 | MG25: -1 | MH25: -1 | MI25: -1 | MJ25: -1 | MK25: -1 | ML25: -1 | MM25: -1 | MN25: -1 | MO25: -1 | MP25: -1 | MQ25: -1 | MR25: -1 | MS25: -1 | MT25: -1 | MU25: -1 | MV25: -1 | MW25: -1 | MX25: -1 | MY25: -1 | MZ25: -1 | NA25: -1 | NB25: -1 | NC25: -1 | ND25: -1 | NE25: -1 | NF25: -1 | NG25: -1 | NH25: -1 | NI25: -1 | NJ25: -1 | NK25: -1 | NL25: -1 | NM25: -1 | NN25: -1 | NO25: -1 | NP25: -1 | NQ25: -1 | NR25: -1 | NS25: -1 | NT25: -1 | NU25: -1 | NV25: -1 | NW25: -1 | NX25: -1 | NY25: -1 | NZ25: -1 | OA25: -1 | OB25: -1 | OC25: -1 | OD25: -1 | OE25: -1 | OF25: -1 | OG25: -1 | OH25: -1 | OI25: -1 | OJ25: -1 | OK25: -1 | OL25: -1
A26: 1.99 | B26: -1 | C26: -1 | D26: -1 | E26: -1 | F26: -1 | G26: -1 | H26: -1 | I26: -1 | J26: -1 | K26: -1 | L26: -1 | M26: -1 | N26: -1 | O26: -1 | P26: -1 | Q26: -1 | R26: -1 | S26: -1 | T26: -1 | U26: -1 | V26: -1 | W26: -1 | X26: -1 | Y26: -1 | Z26: -1 | AA26: -1 | AB26: -1 | AC26: -1 | AD26: -1 | AE26: -1 | AF26: -1 | AG26: -1 | AH26: -1 | AI26: -1 | AJ26: -1 | AK26: -1 | AL26: -1 | AM26: -1 | AN26: -1 | AO26: -1 | AP26: -1 | AQ26: -1 | AR26: -1 | AS26: -1 | AT26: -1 | AU26: -1 | AV26: -1 | AW26: -1 | AX26: -1 | AY26: -1 | AZ26: -1 | BA26: -1 | BB26: -1 | BC26: -1 | BD26: -1 | BE26: -1 | BF26: -1 | BG26: -1 | BH26: -1 | BI26: -1 | BJ26: -1 | BK26: -1 | BL26: -1 | BM26: -1 | BN26: -1 | BO26: -1 | BP26: -1 | BQ26: -1 | BR26: -1 | BS26: -1 | BT26: -1 | BU26: -1 | BV26: -1 | BW26: -1 | BX26: -1 | BY26: -1 | BZ26: -1 | CA26: -1 | CB26: -1 | CC26: -1 | CD26: -1 | CE26: -1 | CF26: -1 | CG26: -1 | CH26: -1 | CI26: -1 | CJ26: -1 | CK26: -1 | CL26: -1 | CM26: -1 | CN26: -1 | CO26: -1 | CP26: -1 | CQ26: -1 | CR26: -1 | CS26: -1 | CT26: -1 | CU26: -1 | CV26: -1 | CW26: -1 | CX26: -1 | CY26: -1 | CZ26: -1 | DA26: -1 | DB26: -1 | DC26: -1 | DD26: -1 | DE26: -1 | DF26: -1 | DG26: -1 | DH26: -1 | DI26: -1 | DJ26: -1 | DK26: -1 | DL26: -1 | DM26: -1 | DN26: -1 | DO26: -1 | DP26: -1 | DQ26: -1 | DR26: -1 | DS26: -1 | DT26: -1 | DU26: -1 | DV26: -1 | DW26: -1 | DX26: -1 | DY26: -1 | DZ26: -1 | EA26: -1 | EB26: -1 | EC26: -1 | ED26: -1 | EE26: -1 | EF26: -1 | EG26: -1 | EH26: -1 | EI26: -1 | EJ26: -1 | EK26: -1 | EL26: -1 | EM26: -1 | EN26: -1 | EO26: -1 | EP26: -1 | EQ26: -1 | ER26: -1 | ES26: -1 | ET26: -1 | EU26: -1 | EV26: -1 | EW26: -1 | EX26: -1 | EY26: -1 | EZ26: -1 | FA26: -1 | FB26: -1 | FC26: -1 | FD26: -1 | FE26: -1 | FF26: -1 | FG26: -1 | FH26: -1 | FI26: -1 | FJ26: -1 | FK26: -1 | FL26: -1 | FM26: -1 | FN26: -1 | FO26: -1 | FP26: -1 | FQ26: -1 | FR26: -1 | FS26: -1 | FT26: -1 | FU26: -1 | FV26: -1 | FW26: -1 | FX26: -1 | FY26: -1 | FZ26: -1 | GA26: -1 | GB26: -1 | GC26: -1 | GD26: -1 | GE26: -1 | GF26: -1 | GG26: -1 | GH26: -1 | GI26: -1 | GJ26: -1 | GK26: -1 | GL26: -1 | GM26: -1 | GN26: -1 | GO26: -1 | GP26: -1 | GQ26: -1 | GR26: -1 | GS26: -1 | GT26: -1 | GU26: -1 | GV26: -1 | GW26: -1 | GX26: -1 | GY26: -1 | GZ26: -1 | HA26: -1 | HB26: -1 | HC26: -1 | HD26: -1 | HE26: -1 | HF26: -1 | HG26: -1 | HH26: -1 | HI26: -1 | HJ26: -1 | HK26: -1 | HL26: -1 | HM26: -1 | HN26: -1 | HO26: -1 | HP26: -1 | HQ26: -1 | HR26: -1 | HS26: -1 | HT26: -1 | HU26: -1 | HV26: -1 | HW26: -1 | HX26: -1 | HY26: -1 | HZ26: -1 | IA26: -1 | IB26: -1 | IC26: -1 | ID26: -1 | IE26: -1 | IF26: -1 | IG26: -1 | IH26: -1 | II26: -1 | IJ26: -1 | IK26: -1 | IL26: -1 | IM26: -1 | IN26: -1 | IO26: -1 | IP26: -1 | IQ26: -1 | IR26: -1 | IS26: -1 | IT26: -1 | IU26: -1 | IV26: -1 | IW26: -1 | IX26: -1 | IY26: -1 | IZ26: -1 | JA26: -1 | JB26: -1 | JC26: -1 | JD26: -1 | JE26: -1 | JF26: -1 | JG26: -1 | JH26: -1 | JI26: -1 | JJ26: -1 | JK26: -1 | JL26: -1 | JM26: -1 | JN26: -1 | JO26: -1 | JP26: -1 | JQ26: -1 | JR26: -1 | JS26: -1 | JT26: -1 | JU26: -1 | JV26: -1 | JW26: -1 | JX26: -1 | JY26: -1 | JZ26: -1 | KA26: -1 | KB26: -1 | KC26: -1 | KD26: -1 | KE26: -1 | KF26: -1 | KG26: -1 | KH26: -1 | KI26: -1 | KJ26: -1 | KK26: -1 | KL26: -1 | KM26: -1 | KN26: -1 | KO26: -1 | KP26: -1 | KQ26: -1 | KR26: -1 | KS26: -1 | KT26: -1 | KU26: -1 | KV26: -1 | KW26: -1 | KX26: -1 | KY26: -1 | KZ26: -1 | LA26: -1 | LB26: -1 | LC26: -1 | LD26: -1 | LE26: -1 | LF26: -1 | LG26: -1 | LH26: -1 | LI26: -1 | LJ26: -1 | LK26: -1 | LL26: -1 | LM26: -1 | LN26: -1 | LO26: -1 | LP26: -1 | LQ26: -1 | LR26: -1 | LS26: -1 | LT26: -1 | LU26: -1 | LV26: -1 | LW26: -1 | LX26: -1 | LY26: -1 | LZ26: -1 | MA26: -1 | MB26: -1 | MC26: -1 | MD26: -1 | ME26: -1 | MF26: -1 | MG26: -1 | MH26: -1 | MI26: -1 | MJ26: -1 | MK26: -1 | ML26: -1 | MM26: -1 | MN26: -1 | MO26: -1 | MP26: -1 | MQ26: -1 | MR26: -1 | MS26: -1 | MT26: -1 | MU26: -1 | MV26: -1 | MW26: -1 | MX26: -1 | MY26: -1 | MZ26: -1 | NA26: -1 | NB26: -1 | NC26: -1 | ND26: -1 | NE26: -1 | NF26: -1 | NG26: -1 | NH26: -1 | NI26: -1 | NJ26: -1 | NK26: -1 | NL26: -1 | NM26: -1 | NN26: -1 | NO26: -1 | NP26: -1 | NQ26: -1 | NR26: -1 | NS26: -1 | NT26: -1 | NU26: -1 | NV26: -1 | NW26: -1 | NX26: -1 | NY26: -1 | NZ26: -1 | OA26: -1 | OB26: -1 | OC26: -1 | OD26: -1 | OE26: -1 | OF26: -1 | OG26: -1 | OH26: -1 | OI26: -1 | OJ26: -1 | OK26: -1 | OL26: -1
A27: 1.98 | B27: -1 | C27: -1 | D27: -1 | E27: -1 | F27: -1 | G27: -1 | H27: -1 | I27: -1 | J27: -1 | K27: -1 | L27: -1 | M27: -1 | N27: -1 | O27: -1 | P27: -1 | Q27: -1 | R27: -1 | S27: -1 | T27: -1 | U27: -1 | V27: -1 | W27: -1 | X27: -1 | Y27: -1 | Z27: -1 | AA27: -1 | AB27: -1 | AC27: -1 | AD27: -1 | AE27: -1 | AF27: -1 | AG27: -1 | AH27: -1 | AI27: -1 | AJ27: -1 | AK27: -1 | AL27: -1 | AM27: -1 | AN27: -1 | AO27: -1 | AP27: -1 | AQ27: -1 | AR27: -1 | AS27: -1 | AT27: -1 | AU27: -1 | AV27: -1 | AW27: -1 | AX27: -1 | AY27: -1 | AZ27: -1 | BA27: -1 | BB27: -1 | BC27: -1 | BD27: -1 | BE27: -1 | BF27: -1 | BG27: -1 | BH27: -1 | BI27: -1 | BJ27: -1 | BK27: -1 | BL27: -1 | BM27: -1 | BN27: -1 | BO27: -1 | BP27: -1 | BQ27: -1 | BR27: -1 | BS27: -1 | BT27: -1 | BU27: -1 | BV27: -1 | BW27: -1 | BX27: -1 | BY27: -1 | BZ27: -1 | CA27: -1 | CB27: -1 | CC27: -1 | CD27: -1 | CE27: -1 | CF27: -1 | CG27: -1 | CH27: -1 | CI27: -1 | CJ27: -1 | CK27: -1 | CL27: -1 | CM27: -1 | CN27: -1 | CO27: -1 | CP27: -1 | CQ27: -1 | CR27: -1 | CS27: -1 | CT27: -1 | CU27: -1 | CV27: -1 | CW27: -1 | CX27: -1 | CY27: -1 | CZ27: -1 | DA27: -1 | DB27: -1 | DC27: -1 | DD27: -1 | DE27: -1 | DF27: -1 | DG27: -1 | DH27: -1 | DI27: -1 | DJ27: -1 | DK27: -1 | DL27: -1 | DM27: -1 | DN27: -1 | DO27: -1 | DP27: -1 | DQ27: -1 | DR27: -1 | DS27: -1 | DT27: -1 | DU27: -1 | DV27: -1 | DW27: -1 | DX27: -1 | DY27: -1 | DZ27: -1 | EA27: -1 | EB27: -1 | EC27: -1 | ED27: -1 | EE27: -1 | EF27: -1 | EG27: -1 | EH27: -1 | EI27: -1 | EJ27: -1 | EK27: -1 | EL27: -1 | EM27: -1 | EN27: -1 | EO27: -1 | EP27: -1 | EQ27: -1 | ER27: -1 | ES27: -1 | ET27: -1 | EU27: -1 | EV27: -1 | EW27: -1 | EX27: -1 | EY27: -1 | EZ27: -1 | FA27: -1 | FB27: -1 | FC27: -1 | FD27: -1 | FE27: -1 | FF27: -1 | FG27: -1 | FH27: -1 | FI27: -1 | FJ27: -1 | FK27: -1 | FL27: -1 | FM27: -1 | FN27: -1 | FO27: -1 | FP27: -1 | FQ27: -1 | FR27: -1 | FS27: -1 | FT27: -1 | FU27: -1 | FV27: -1 | FW27: -1 | FX27: -1 | FY27: -1 | FZ27: -1 | GA27: -1 | GB27: -1 | GC27: -1 | GD27: -1 | GE27: -1 | GF27: -1 | GG27: -1 | GH27: -1 | GI27: -1 | GJ27: -1 | GK27: -1 | GL27: -1 | GM27: -1 | GN27: -1 | GO27: -1 | GP27: -1 | GQ27: -1 | GR27: -1 | GS27: -1 | GT27: -1 | GU27: -1 | GV27: -1 | GW27: -1 | GX27: -1 | GY27: -1 | GZ27: -1 | HA27: -1 | HB27: -1 | HC27: -1 | HD27: -1 | HE27: -1 | HF27: -1 | HG27: -1 | HH27: -1 | HI27: -1 | HJ27: -1 | HK27: -1 | HL27: -1 | HM27: -1 | HN27: -1 | HO27: -1 | HP27: -1 | HQ27: -1 | HR27: -1 | HS27: -1 | HT27: -1 | HU27: -1 | HV27: -1 | HW27: -1 | HX27: -1 | HY27: -1 | HZ27: -1 | IA27: -1 | IB27: -1 | IC27: -1 | ID27: -1 | IE27: -1 | IF27: -1 | IG27: -1 | IH27: -1 | II27: -1 | IJ27: -1 | IK27: -1 | IL27: -1 | IM27: -1 | IN27: -1 | IO27: -1 | IP27: -1 | IQ27: -1 | IR27: -1 | IS27: -1 | IT27: -1 | IU27: -1 | IV27: -1 | IW27: -1 | IX27: -1 | IY27: -1 | IZ27: -1 | JA27: -1 | JB27: -1 | JC27: -1 | JD27: -1 | JE27: -1 | JF27: -1 | JG27: -1 | JH27: -1 | JI27: -1 | JJ27: -1 | JK27: -1 | JL27: -1 | JM27: -1 | JN27: -1 | JO27: -1 | JP27: -1 | JQ27: -1 | JR27: -1 | JS27: -1 | JT27: -1 | JU27: -1 | JV27: -1 | JW27: -1 | JX27: -1 | JY27: -1 | JZ27: -1 | KA27: -1 | KB27: -1 | KC27: -1 | KD27: -1 | KE27: -1 | KF27: -1 | KG27: -1 | KH27: -1 | KI27: -1 | KJ27: -1 | KK27: -1 | KL27: -1 | KM27: -1 | KN27: -1 | KO27: -1 | KP27: -1 | KQ27: -1 | KR27: -1 | KS27: -1 | KT27: -1 | KU27: -1 | KV27: -1 | KW27: -1 | KX27: -1 | KY27: -1 | KZ27: -1 | LA27: -1 | LB27: -1 | LC27: -1 | LD27: -1 | LE27: -1 | LF27: -1 | LG27: -1 | LH27: -1 | LI27: -1 | LJ27: -1 | LK27: -1 | LL27: -1 | LM27: -1 | LN27: -1 | LO27: -1 | LP27: -1 | LQ27: -1 | LR27: -1 | LS27: -1 | LT27: -1 | LU27: -1 | LV27: -1 | LW27: -1 | LX27: -1 | LY27: -1 | LZ27: -1 | MA27: -1 | MB27: -1 | MC27: -1 | MD27: -1 | ME27: -1 | MF27: -1 | MG27: -1 | MH27: -1 | MI27: -1 | MJ27: -1 | MK27: -1 | ML27: -1 | MM27: -1 | MN27: -1 | MO27: -1 | MP27: -1 | MQ27: -1 | MR27: -1 | MS27: -1 | MT27: -1 | MU27: -1 | MV27: -1 | MW27: -1 | MX27: -1 | MY27: -1 | MZ27: -1 | NA27: -1 | NB27: -1 | NC27: -1 | ND27: -1 | NE27: -1 | NF27: -1 | NG27: -1 | NH27: -1 | NI27: -1 | NJ27: -1 | NK27: -1 | NL27: -1 | NM27: -1 | NN27: -1 | NO27: -1 | NP27: -1 | NQ27: -1 | NR27: -1 | NS27: -1 | NT27: -1 | NU27: -1 | NV27: -1 | NW27: -1 | NX27: -1 | NY27: -1 | NZ27: -1 | OA27: -1 | OB27: -1 | OC27: -1 | OD27: -1 | OE27: -1 | OF27: -1 | OG27: -1 | OH27: -1 | OI27: -1 | OJ27: -1 | OK27: -1 | OL27: -1
A28: 1.97 | B28: -1 | C28: -1 | D28: -1 | E28: -1 | F28: -1 | G28: -1 | H28: -1 | I28: -1 | J28: -1 | K28: -1 | L28: -1 | M28: -1 | N28: -1 | O28: -1 | P28: -1 | Q28: -1 | R28: -1 | S28: -1 | T28: -1 | U28: -1 | V28: -1 | W28: -1 | X28: -1 | Y28: -1 | Z28: -1 | AA28: -1 | AB28: -1 | AC28: -1 | AD28: -1 | AE28: -1 | AF28: -1 | AG28: -1 | AH28: -1 | AI28: -1 | AJ28: -1 | AK28: -1 | AL28: -1 | AM28: -1 | AN28: -1 | AO28: -1 | AP28: -1 | AQ28: -1 | AR28: -1 | AS28: -1 | AT28: -1 | AU28: -1 | AV28: -1 | AW28: -1 | AX28: -1 | AY28: -1 | AZ28: -1 | BA28: -1 | BB28: -1 | BC28: -1 | BD28: -1 | BE28: -1 | BF28: -1 | BG28: -1 | BH28: -1 | BI28: -1 | BJ28: -1 | BK28: -1 | BL28: -1 | BM28: -1 | BN28: -1 | BO28: -1 | BP28: -1 | BQ28: -1 | BR28: -1 | BS28: -1 | BT28: -1 | BU28: -1 | BV28: -1 | BW28: -1 | BX28: -1 | BY28: -1 | BZ28: -1 | CA28: -1 | CB28: -1 | CC28: -1 | CD28: -1 | CE28: -1 | CF28: -1 | CG28: -1 | CH28: -1 | CI28: -1 | CJ28: -1 | CK28: -1 | CL28: -1 | CM28: -1 | CN28: -1 | CO28: -1 | CP28: -1 | CQ28: -1 | CR28: -1 | CS28: -1 | CT28: -1 | CU28: -1 | CV28: -1 | CW28: -1 | CX28: -1 | CY28: -1 | CZ28: -1 | DA28: -1 | DB28: -1 | DC28: -1 | DD28: -1 | DE28: -1 | DF28: -1 | DG28: -1 | DH28: -1 | DI28: -1 | DJ28: -1 | DK28: -1 | DL28: -1 | DM28: -1 | DN28: -1 | DO28: -1 | DP28: -1 | DQ28: -1 | DR28: -1 | DS28: -1 | DT28: -1 | DU28: -1 | DV28: -1 | DW28: -1 | DX28: -1 | DY28: -1 | DZ28: -1 | EA28: -1 | EB28: -1 | EC28: -1 | ED28: -1 | EE28: -1 | EF28: -1 | EG28: -1 | EH28: -1 | EI28: -1 | EJ28: -1 | EK28: -1 | EL28: -1 | EM28: -1 | EN28: -1 | EO28: -1 | EP28: -1 | EQ28: -1 | ER28: -1 | ES28: -1 | ET28: -1 | EU28: -1 | EV28: -1 | EW28: -1 | EX28: -1 | EY28: -1 | EZ28: -1 | FA28: -1 | FB28: -1 | FC28: -1 | FD28: -1 | FE28: -1 | FF28: -1 | FG28: -1 | FH28: -1 | FI28: -1 | FJ28: -1 | FK28: -1 | FL28: -1 | FM28: -1 | FN28: -1 | FO28: -1 | FP28: -1 | FQ28: -1 | FR28: -1 | FS28: -1 | FT28: -1 | FU28: -1 | FV28: -1 | FW28: -1 | FX28: -1 | FY28: -1 | FZ28: -1 | GA28: -1 | GB28: -1 | GC28: -1 | GD28: -1 | GE28: -1 | GF28: -1 | GG28: -1 | GH28: -1 | GI28: -1 | GJ28: -1 | GK28: -1 | GL28: -1 | GM28: -1 | GN28: -1 | GO28: -1 | GP28: -1 | GQ28: -1 | GR28: -1 | GS28: -1 | GT28: -1 | GU28: -1 | GV28: -1 | GW28: -1 | GX28: -1 | GY28: -1 | GZ28: -1 | HA28: -1 | HB28: -1 | HC28: -1 | HD28: -1 | HE28: -1 | HF28: -1 | HG28: -1 | HH28: -1 | HI28: -1 | HJ28: -1 | HK28: -1 | HL28: -1 | HM28: -1 | HN28: -1 | HO28: -1 | HP28: -1 | HQ28: -1 | HR28: -1 | HS28: -1 | HT28: -1 | HU28: -1 | HV28: -1 | HW28: -1 | HX28: -1 | HY28: -1 | HZ28: -1 | IA28: -1 | IB28: -1 | IC28: -1 | ID28: -1 | IE28: -1 | IF28: -1 | IG28: -1 | IH28: -1 | II28: -1 | IJ28: -1 | IK28: -1 | IL28: -1 | IM28: -1 | IN28: -1 | IO28: -1 | IP28: -1 | IQ28: -1 | IR28: -1 | IS28: -1 | IT28: -1 | IU28: -1 | IV28: -1 | IW28: -1 | IX28: -1 | IY28: -1 | IZ28: -1 | JA28: -1 | JB28: -1 | JC28: -1 | JD28: -1 | JE28: -1 | JF28: -1 | JG28: -1 | JH28: -1 | JI28: -1 | JJ28: -1 | JK28: -1 | JL28: -1 | JM28: -1 | JN28: -1 | JO28: -1 | JP28: -1 | JQ28: -1 | JR28: -1 | JS28: -1 | JT28: -1 | JU28: -1 | JV28: -1 | JW28: -1 | JX28: -1 | JY28: -1 | JZ28: -1 | KA28: -1 | KB28: -1 | KC28: -1 | KD28: -1 | KE28: -1 | KF28: -1 | KG28: -1 | KH28: -1 | KI28: -1 | KJ28: -1 | KK28: -1 | KL28: -1 | KM28: -1 | KN28: -1 | KO28: -1 | KP28: -1 | KQ28: -1 | KR28: -1 | KS28: -1 | KT28: -1 | KU28: -1 | KV28: -1 | KW28: -1 | KX28: -1 | KY28: -1 | KZ28: -1 | LA28: -1 | LB28: -1 | LC28: -1 | LD28: -1 | LE28: -1 | LF28: -1 | LG28: -1 | LH28: -1 | LI28: -1 | LJ28: -1 | LK28: -1 | LL28: -1 | LM28: -1 | LN28: -1 | LO28: -1 | LP28: -1 | LQ28: -1 | LR28: -1 | LS28: -1 | LT28: -1 | LU28: -1 | LV28: -1 | LW28: -1 | LX28: -1 | LY28: -1 | LZ28: -1 | MA28: -1 | MB28: -1 | MC28: -1 | MD28: -1 | ME28: -1 | MF28: -1 | MG28: -1 | MH28: -1 | MI28: -1 | MJ28: -1 | MK28: -1 | ML28: -1 | MM28: -1 | MN28: -1 | MO28: -1 | MP28: -1 | MQ28: -1 | MR28: -1 | MS28: -1 | MT28: -1 | MU28: -1 | MV28: -1 | MW28: -1 | MX28: -1 | MY28: -1 | MZ28: -1 | NA28: -1 | NB28: -1 | NC28: -1 | ND28: -1 | NE28: -1 | NF28: -1 | NG28: -1 | NH28: -1 | NI28: -1 | NJ28: -1 | NK28: -1 | NL28: -1 | NM28: -1 | NN28: -1 | NO28: -1 | NP28: -1 | NQ28: -1 | NR28: -1 | NS28: -1 | NT28: -1 | NU28: -1 | NV28: -1 | NW28: -1 | NX28: -1 | NY28: -1 | NZ28: -1 | OA28: -1 | OB28: -1 | OC28: -1 | OD28: -1 | OE28: -1 | OF28: -1 | OG28: -1 | OH28: -1 | OI28: -1 | OJ28: -1 | OK28: -1 | OL28: -1
A29: 1.96 | B29: -1 | C29: -1 | D29: -1 | E29: -1 | F29: -1 | G29: -1 | H29: -1 | I29: -1 | J29: -1 | K29: -1 | L29: -1 | M29: -1 | N29: -1 | O29: -1 | P29: -1 | Q29: -1 | R29: -1 | S29: -1 | T29: -1 | U29: -1 | V29: -1 | W29: -1 | X29: -1 | Y29: -1 | Z29: -1 | AA29: -1 | AB29: -1 | AC29: -1 | AD29: -1 | AE29: -1 | AF29: -1 | AG29: -1 | AH29: -1 | AI29: -1 | AJ29: -1 | AK29: -1 | AL29: -1 | AM29: -1 | AN29: -1 | AO29: -1 | AP29: -1 | AQ29: -1 | AR29: -1 | AS29: -1 | AT29: -1 | AU29: -1 | AV29: -1 | AW29: -1 | AX29: -1 | AY29: -1 | AZ29: -1 | BA29: -1 | BB29: -1 | BC29: -1 | BD29: -1 | BE29: -1 | BF29: -1 | BG29: -1 | BH29: -1 | BI29: -1 | BJ29: -1 | BK29: -1 | BL29: -1 | BM29: -1 | BN29: -1 | BO29: -1 | BP29: -1 | BQ29: -1 | BR29: -1 | BS29: -1 | BT29: -1 | BU29: -1 | BV29: -1 | BW29: -1 | BX29: -1 | BY29: -1 | BZ29: -1 | CA29: -1 | CB29: -1 | CC29: -1 | CD29: -1 | CE29: -1 | CF29: -1 | CG29: -1 | CH29: -1 | CI29: -1 | CJ29: -1 | CK29: -1 | CL29: -1 | CM29: -1 | CN29: -1 | CO29: -1 | CP29: -1 | CQ29: -1 | CR29: -1 | CS29: -1 | CT29: -1 | CU29: -1 | CV29: -1 | CW29: -1 | CX29: -1 | CY29: -1 | CZ29: -1 | DA29: -1 | DB29: -1 | DC29: -1 | DD29: -1 | DE29: -1 | DF29: -1 | DG29: -1 | DH29: -1 | DI29: -1 | DJ29: -1 | DK29: -1 | DL29: -1 | DM29: -1 | DN29: -1 | DO29: -1 | DP29: -1 | DQ29: -1 | DR29: -1 | DS29: -1 | DT29: -1 | DU29: -1 | DV29: -1 | DW29: -1 | DX29: -1 | DY29: -1 | DZ29: -1 | EA29: -1 | EB29: -1 | EC29: -1 | ED29: -1 | EE29: -1 | EF29: -1 | EG29: -1 | EH29: -1 | EI29: -1 | EJ29: -1 | EK29: -1 | EL29: -1 | EM29: -1 | EN29: -1 | EO29: -1 | EP29: -1 | EQ29: -1 | ER29: -1 | ES29: -1 | ET29: -1 | EU29: -1 | EV29: -1 | EW29: -1 | EX29: -1 | EY29: -1 | EZ29: -1 | FA29: -1 | FB29: -1 | FC29: -1 | FD29: -1 | FE29: -1 | FF29: -1 | FG29: -1 | FH29: -1 | FI29: -1 | FJ29: -1 | FK29: -1 | FL29: -1 | FM29: -1 | FN29: -1 | FO29: -1 | FP29: -1 | FQ29: -1 | FR29: -1 | FS29: -1 | FT29: -1 | FU29: -1 | FV29: -1 | FW29: -1 | FX29: -1 | FY29: -1 | FZ29: -1 | GA29: -1 | GB29: -1 | GC29: -1 | GD29: -1 | GE29: -1 | GF29: -1 | GG29: -1 | GH29: -1 | GI29: -1 | GJ29: -1 | GK29: -1 | GL29: -1 | GM29: -1 | GN29: -1 | GO29: -1 | GP29: -1 | GQ29: -1 | GR29: -1 | GS29: -1 | GT29: -1 | GU29: -1 | GV29: -1 | GW29: -1 | GX29: -1 | GY29: -1 | GZ29: -1 | HA29: -1 | HB29: -1 | HC29: -1 | HD29: -1 | HE29: -1 | HF29: -1 | HG29: -1 | HH29: -1 | HI29: -1 | HJ29: -1 | HK29: -1 | HL29: -1 | HM29: -1 | HN29: -1 | HO29: -1 | HP29: -1 | HQ29: -1 | HR29: -1 | HS29: -1 | HT29: -1 | HU29: -1 | HV29: -1 | HW29: -1 | HX29: -1 | HY29: -1 | HZ29: -1 | IA29: -1 | IB29: -1 | IC29: -1 | ID29: -1 | IE29: -1 | IF29: -1 | IG29: -1 | IH29: -1 | II29: -1 | IJ29: -1 | IK29: -1 | IL29: -1 | IM29: -1 | IN29: -1 | IO29: -1 | IP29: -1 | IQ29: -1 | IR29: -1 | IS29: -1 | IT29: -1 | IU29: -1 | IV29: -1 | IW29: -1 | IX29: -1 | IY29: -1 | IZ29: -1 | JA29: -1 | JB29: -1 | JC29: -1 | JD29: -1 | JE29: -1 | JF29: -1 | JG29: -1 | JH29: -1 | JI29: -1 | JJ29: -1 | JK29: -1 | JL29: -1 | JM29: -1 | JN29: -1 | JO29: -1 | JP29: -1 | JQ29: -1 | JR29: -1 | JS29: -1 | JT29: -1 | JU29: -1 | JV29: -1 | JW29: -1 | JX29: -1 | JY29: -1 | JZ29: -1 | KA29: -1 | KB29: -1 | KC29: -1 | KD29: -1 | KE29: -1 | KF29: -1 | KG29: -1 | KH29: -1 | KI29: -1 | KJ29: -1 | KK29: -1 | KL29: -1 | KM29: -1 | KN29: -1 | KO29: -1 | KP29: -1 | KQ29: -1 | KR29: -1 | KS29: -1 | KT29: -1 | KU29: -1 | KV29: -1 | KW29: -1 | KX29: -1 | KY29: -1 | KZ29: -1 | LA29: -1 | LB29: -1 | LC29: -1 | LD29: -1 | LE29: -1 | LF29: -1 | LG29: -1 | LH29: -1 | LI29: -1 | LJ29: -1 | LK29: -1 | LL29: -1 | LM29: -1 | LN29: -1 | LO29: -1 | LP29: -1 | LQ29: -1 | LR29: -1 | LS29: -1 | LT29: -1 | LU29: -1 | LV29: -1 | LW29: -1 | LX29: -1 | LY29: -1 | LZ29: -1 | MA29: -1 | MB29: -1 | MC29: -1 | MD29: -1 | ME29: -1 | MF29: -1 | MG29: -1 | MH29: -1 | MI29: -1 | MJ29: -1 | MK29: -1 | ML29: -1 | MM29: -1 | MN29: -1 | MO29: -1 | MP29: -1 | MQ29: -1 | MR29: -1 | MS29: -1 | MT29: -1 | MU29: -1 | MV29: -1 | MW29: -1 | MX29: -1 | MY29: -1 | MZ29: -1 | NA29: -1 | NB29: -1 | NC29: -1 | ND29: -1 | NE29: -1 | NF29: -1 | NG29: -1 | NH29: -1 | NI29: -1 | NJ29: -1 | NK29: -1 | NL29: -1 | NM29: -1 | NN29: -1 | NO29: -1 | NP29: -1 | NQ29: -1 | NR29: -1 | NS29: -1 | NT29: -1 | NU29: -1 | NV29: -1 | NW29: -1 | NX29: -1 | NY29: -1 | NZ29: -1 | OA29: -1 | OB29: -1 | OC29: -1 | OD29: -1 | OE29: -1 | OF29: -1 | OG29: -1 | OH29: -1 | OI29: -1 | OJ29: -1 | OK29: -1 | OL29: -1
A30: 1.95 | B30: -1 | C30: -1 | D30: -1 | E30: -1 | F30: -1 | G30: -1 | H30: -1 | I30: -1 | J30: -1 | K30: -1 | L30: -1 | M30: -1 | N30: -1 | O30: -1 | P30: -1 | Q30: -1 | R30: -1 | S30: -1 | T30: -1 | U30: -1 | V30: -1 | W30: -1 | X30: -1 | Y30: -1 | Z30: -1 | AA30: -1 | AB30: -1 | AC30: -1 | AD30: -1 | AE30: -1 | AF30: -1 | AG30: -1 | AH30: -1 | AI30: -1 | AJ30: -1 | AK30: -1 | AL30: -1 | AM30: -1 | AN30: -1 | AO30: -1 | AP30: -1 | AQ30: -1 | AR30: -1 | AS30: -1 | AT30: -1 | AU30: -1 | AV30: -1 | AW30: -1 | AX30: -1 | AY30: -1 | AZ30: -1 | BA30: -1 | BB30: -1 | BC30: -1 | BD30: -1 | BE30: -1 | BF30: -1 | BG30: -1 | BH30: -1 | BI30: -1 | BJ30: -1 | BK30: -1 | BL30: -1 | BM30: -1 | BN30: -1 | BO30: -1 | BP30: -1 | BQ30: -1 | BR30: -1 | BS30: -1 | BT30: -1 | BU30: -1 | BV30: -1 | BW30: -1 | BX30: -1 | BY30: -1 | BZ30: -1 | CA30: -1 | CB30: -1 | CC30: -1 | CD30: -1 | CE30: -1 | CF30: -1 | CG30: -1 | CH30: -1 | CI30: -1 | CJ30: -1 | CK30: -1 | CL30: -1 | CM30: -1 | CN30: -1 | CO30: -1 | CP30: -1 | CQ30: -1 | CR30: -1 | CS30: -1 | CT30: -1 | CU30: -1 | CV30: -1 | CW30: -1 | CX30: -1 | CY30: -1 | CZ30: -1 | DA30: -1 | DB30: -1 | DC30: -1 | DD30: -1 | DE30: -1 | DF30: -1 | DG30: -1 | DH30: -1 | DI30: -1 | DJ30: -1 | DK30: -1 | DL30: -1 | DM30: -1 | DN30: -1 | DO30: -1 | DP30: -1 | DQ30: -1 | DR30: -1 | DS30: -1 | DT30: -1 | DU30: -1 | DV30: -1 | DW30: -1 | DX30: -1 | DY30: -1 | DZ30: -1 | EA30: -1 | EB30: -1 | EC30: -1 | ED30: -1 | EE30: -1 | EF30: -1 | EG30: -1 | EH30: -1 | EI30: -1 | EJ30: -1 | EK30: -1 | EL30: -1 | EM30: -1 | EN30: -1 | EO30: -1 | EP30: -1 | EQ30: -1 | ER30: -1 | ES30: -1 | ET30: -1 | EU30: -1 | EV30: -1 | EW30: -1 | EX30: -1 | EY30: -1 | EZ30: -1 | FA30: -1 | FB30: -1 | FC30: -1 | FD30: -1 | FE30: -1 | FF30: -1 | FG30: -1 | FH30: -1 | FI30: -1 | FJ30: -1 | FK30: -1 | FL30: -1 | FM30: -1 | FN30: -1 | FO30: -1 | FP30: -1 | FQ30: -1 | FR30: -1 | FS30: -1 | FT30: -1 | FU30: -1 | FV30: -1 | FW30: -1 | FX30: -1 | FY30: -1 | FZ30: -1 | GA30: -1 | GB30: -1 | GC30: -1 | GD30: -1 | GE30: -1 | GF30: -1 | GG30: -1 | GH30: -1 | GI30: -1 | GJ30: -1 | GK30: -1 | GL30: -1 | GM30: -1 | GN30: -1 | GO30: -1 | GP30: -1 | GQ30: -1 | GR30: -1 | GS30: -1 | GT30: -1 | GU30: -1 | GV30: -1 | GW30: -1 | GX30: -1 | GY30: -1 | GZ30: -1 | HA30: -1 | HB30: -1 | HC30: -1 | HD30: -1 | HE30: -1 | HF30: -1 | HG30: -1 | HH30: -1 | HI30: -1 | HJ30: -1 | HK30: -1 | HL30: -1 | HM30: -1 | HN30: -1 | HO30: -1 | HP30: -1 | HQ30: -1 | HR30: -1 | HS30: -1 | HT30: -1 | HU30: -1 | HV30: -1 | HW30: -1 | HX30: -1 | HY30: -1 | HZ30: -1 | IA30: -1 | IB30: -1 | IC30: -1 | ID30: -1 | IE30: -1 | IF30: -1 | IG30: -1 | IH30: -1 | II30: -1 | IJ30: -1 | IK30: -1 | IL30: -1 | IM30: -1 | IN30: -1 | IO30: -1 | IP30: -1 | IQ30: -1 | IR30: -1 | IS30: -1 | IT30: -1 | IU30: -1 | IV30: -1 | IW30: -1 | IX30: -1 | IY30: -1 | IZ30: -1 | JA30: -1 | JB30: -1 | JC30: -1 | JD30: -1 | JE30: -1 | JF30: -1 | JG30: -1 | JH30: -1 | JI30: -1 | JJ30: -1 | JK30: -1 | JL30: -1 | JM30: -1 | JN30: -1 | JO30: -1 | JP30: -1 | JQ30: -1 | JR30: -1 | JS30: -1 | JT30: -1 | JU30: -1 | JV30: -1 | JW30: -1 | JX30: -1 | JY30: -1 | JZ30: -1 | KA30: -1 | KB30: -1 | KC30: -1 | KD30: -1 | KE30: -1 | KF30: -1 | KG30: -1 | KH30: -1 | KI30: -1 | KJ30: -1 | KK30: -1 | KL30: -1 | KM30: -1 | KN30: -1 | KO30: -1 | KP30: -1 | KQ30: -1 | KR30: -1 | KS30: -1 | KT30: -1 | KU30: -1 | KV30: -1 | KW30: -1 | KX30: -1 | KY30: -1 | KZ30: -1 | LA30: -1 | LB30: -1 | LC30: -1 | LD30: -1 | LE30: -1 | LF30: -1 | LG30: -1 | LH30: -1 | LI30: -1 | LJ30: -1 | LK30: -1 | LL30: -1 | LM30: -1 | LN30: -1 | LO30: -1 | LP30: -1 | LQ30: -1 | LR30: -1 | LS30: -1 | LT30: -1 | LU30: -1 | LV30: -1 | LW30: -1 | LX30: -1 | LY30: -1 | LZ30: -1 | MA30: -1 | MB30: -1 | MC30: -1 | MD30: -1 | ME30: -1 | MF30: -1 | MG30: -1 | MH30: -1 | MI30: -1 | MJ30: -1 | MK30: -1 | ML30: -1 | MM30: -1 | MN30: -1 | MO30: -1 | MP30: -1 | MQ30: -1 | MR30: -1 | MS30: -1 | MT30: -1 | MU30: -1 | MV30: -1 | MW30: -1 | MX30: -1 | MY30: -1 | MZ30: -1 | NA30: -1 | NB30: -1 | NC30: -1 | ND30: -1 | NE30: -1 | NF30: -1 | NG30: -1 | NH30: -1 | NI30: -1 | NJ30: -1 | NK30: -1 | NL30: -1 | NM30: -1 | NN30: -1 | NO30: -1 | NP30: -1 | NQ30: -1 | NR30: -1 | NS30: -1 | NT30: -1 | NU30: -1 | NV30: -1 | NW30: -1 | NX30: -1 | NY30: -1 | NZ30: -1 | OA30: -1 | OB30: -1 | OC30: -1 | OD30: -1 | OE30: -1 | OF30: -1 | OG30: -1 | OH30: -1 | OI30: -1 | OJ30: -1 | OK30: -1 | OL30: -1
A31: 1.94 | B31: -1 | C31: -1 | D31: -1 | E31: -1 | F31: -1 | G31: -1 | H31: -1 | I31: -1 | J31: -1 | K31: -1 | L31: -1 | M31: -1 | N31: -1 | O31: -1 | P31: -1 | Q31: -1 | R31: -1 | S31: -1 | T31: -1 | U31: -1 | V31: -1 | W31: -1 | X31: -1 | Y31: -1 | Z31: -1 | AA31: -1 | AB31: -1 | AC31: -1 | AD31: -1 | AE31: -1 | AF31: -1 | AG31: -1 | AH31: -1 | AI31: -1 | AJ31: -1 | AK31: -1 | AL31: -1 | AM31: -1 | AN31: -1 | AO31: -1 | AP31: -1 | AQ31: -1 | AR31: -1 | AS31: -1 | AT31: -1 | AU31: -1 | AV31: -1 | AW31: -1 | AX31: -1 | AY31: -1 | AZ31: -1 | BA31: -1 | BB31: -1 | BC31: -1 | BD31: -1 | BE31: -1 | BF31: -1 | BG31: -1 | BH31: -1 | BI31: -1 | BJ31: -1 | BK31: -1 | BL31: -1 | BM31: -1 | BN31: -1 | BO31: -1 | BP31: -1 | BQ31: -1 | BR31: -1 | BS31: -1 | BT31: -1 | BU31: -1 | BV31: -1 | BW31: -1 | BX31: -1 | BY31: -1 | BZ31: -1 | CA31: -1 | CB31: -1 | CC31: -1 | CD31: -1 | CE31: -1 | CF31: -1 | CG31: -1 | CH31: -1 | CI31: -1 | CJ31: -1 | CK31: -1 | CL31: -1 | CM31: -1 | CN31: -1 | CO31: -1 | CP31: -1 | CQ31: -1 | CR31: -1 | CS31: -1 | CT31: -1 | CU31: -1 | CV31: -1 | CW31: -1 | CX31: -1 | CY31: -1 | CZ31: -1 | DA31: -1 | DB31: -1 | DC31: -1 | DD31: -1 | DE31: -1 | DF31: -1 | DG31: -1 | DH31: -1 | DI31: -1 | DJ31: -1 | DK31: -1 | DL31: -1 | DM31: -1 | DN31: -1 | DO31: -1 | DP31: -1 | DQ31: -1 | DR31: -1 | DS31: -1 | DT31: -1 | DU31: -1 | DV31: -1 | DW31: -1 | DX31: -1 | DY31: -1 | DZ31: -1 | EA31: -1 | EB31: -1 | EC31: -1 | ED31: -1 | EE31: -1 | EF31: -1 | EG31: -1 | EH31: -1 | EI31: -1 | EJ31: -1 | EK31: -1 | EL31: -1 | EM31: -1 | EN31: -1 | EO31: -1 | EP31: -1 | EQ31: -1 | ER31: -1 | ES31: -1 | ET31: -1 | EU31: -1 | EV31: -1 | EW31: -1 | EX31: -1 | EY31: -1 | EZ31: -1 | FA31: -1 | FB31: -1 | FC31: -1 | FD31: -1 | FE31: -1 | FF31: -1 | FG31: -1 | FH31: -1 | FI31: -1 | FJ31: -1 | FK31: -1 | FL31: -1 | FM31: -1 | FN31: -1 | FO31: -1 | FP31: -1 | FQ31: -1 | FR31: -1 | FS31: -1 | FT31: -1 | FU31: -1 | FV31: -1 | FW31: -1 | FX31: -1 | FY31: -1 | FZ31: -1 | GA31: -1 | GB31: -1 | GC31: -1 | GD31: -1 | GE31: -1 | GF31: -1 | GG31: -1 | GH31: -1 | GI31: -1 | GJ31: -1 | GK31: -1 | GL31: -1 | GM31: -1 | GN31: -1 | GO31: -1 | GP31: -1 | GQ31: -1 | GR31: -1 | GS31: -1 | GT31: -1 | GU31: -1 | GV31: -1 | GW31: -1 | GX31: -1 | GY31: -1 | GZ31: -1 | HA31: -1 | HB31: -1 | HC31: -1 | HD31: -1 | HE31: -1 | HF31: -1 | HG31: -1 | HH31: -1 | HI31: -1 | HJ31: -1 | HK31: -1 | HL31: -1 | HM31: -1 | HN31: -1 | HO31: -1 | HP31: -1 | HQ31: -1 | HR31: -1 | HS31: -1 | HT31: -1 | HU31: -1 | HV31: -1 | HW31: -1 | HX31: -1 | HY31: -1 | HZ31: -1 | IA31: -1 | IB31: -1 | IC31: -1 | ID31: -1 | IE31: -1 | IF31: -1 | IG31: -1 | IH31: -1 | II31: -1 | IJ31: -1 | IK31: -1 | IL31: -1 | IM31: -1 | IN31: -1 | IO31: -1 | IP31: -1 | IQ31: -1 | IR31: -1 | IS31: -1 | IT31: -1 | IU31: -1 | IV31: -1 | IW31: -1 | IX31: -1 | IY31: -1 | IZ31: -1 | JA31: -1 | JB31: -1 | JC31: -1 | JD31: -1 | JE31: -1 | JF31: -1 | JG31: -1 | JH31: -1 | JI31: -1 | JJ31: -1 | JK31: -1 | JL31: -1 | JM31: -1 | JN31: -1 | JO31: -1 | JP31: -1 | JQ31: -1 | JR31: -1 | JS31: -1 | JT31: -1 | JU31: -1 | JV31: -1 | JW31: -1 | JX31: -1 | JY31: -1 | JZ31: -1 | KA31: -1 | KB31: -1 | KC31: -1 | KD31: -1 | KE31: -1 | KF31: -1 | KG31: -1 | KH31: -1 | KI31: -1 | KJ31: -1 | KK31: -1 | KL31: -1 | KM31: -1 | KN31: -1 | KO31: -1 | KP31: -1 | KQ31: -1 | KR31: -1 | KS31: -1 | KT31: -1 | KU31: -1 | KV31: -1 | KW31: -1 | KX31: -1 | KY31: -1 | KZ31: -1 | LA31: -1 | LB31: -1 | LC31: -1 | LD31: -1 | LE31: -1 | LF31: -1 | LG31: -1 | LH31: -1 | LI31: -1 | LJ31: -1 | LK31: -1 | LL31: -1 | LM31: -1 | LN31: -1 | LO31: -1 | LP31: -1 | LQ31: -1 | LR31: -1 | LS31: -1 | LT31: -1 | LU31: -1 | LV31: -1 | LW31: -1 | LX31: -1 | LY31: -1 | LZ31: -1 | MA31: -1 | MB31: -1 | MC31: -1 | MD31: -1 | ME31: -1 | MF31: -1 | MG31: -1 | MH31: -1 | MI31: -1 | MJ31: -1 | MK31: -1 | ML31: -1 | MM31: -1 | MN31: -1 | MO31: -1 | MP31: -1 | MQ31: -1 | MR31: -1 | MS31: -1 | MT31: -1 | MU31: -1 | MV31: -1 | MW31: -1 | MX31: -1 | MY31: -1 | MZ31: -1 | NA31: -1 | NB31: -1 | NC31: -1 | ND31: -1 | NE31: -1 | NF31: -1 | NG31: -1 | NH31: -1 | NI31: -1 | NJ31: -1 | NK31: -1 | NL31: -1 | NM31: -1 | NN31: -1 | NO31: -1 | NP31: -1 | NQ31: -1 | NR31: -1 | NS31: -1 | NT31: -1 | NU31: -1 | NV31: -1 | NW31: -1 | NX31: -1 | NY31: -1 | NZ31: -1 | OA31: -1 | OB31: -1 | OC31: -1 | OD31: -1 | OE31: -1 | OF31: -1 | OG31: -1 | OH31: -1 | OI31: -1 | OJ31: -1 | OK31: -1 | OL31: -1
A32: 1.93 | B32: -1 | C32: -1 | D32: -1 | E32: -1 | F32: -1 | G32: -1 | H32: -1 | I32: -1 | J32: -1 | K32: -1 | L32: -1 | M32: -1 | N32: -1 | O32: -1 | P32: -1 | Q32: -1 | R32: -1 | S32: -1 | T32: -1 | U32: -1 | V32: -1 | W32: -1 | X32: -1 | Y32: -1 | Z32: -1 | AA32: -1 | AB32: -1 | AC32: -1 | AD32: -1 | AE32: -1 | AF32: -1 | AG32: -1 | AH32: -1 | AI32: -1 | AJ32: -1 | AK32: -1 | AL32: -1 | AM32: -1 | AN32: -1 | AO32: -1 | AP32: -1 | AQ32: -1 | AR32: -1 | AS32: -1 | AT32: -1 | AU32: -1 | AV32: -1 | AW32: -1 | AX32: -1 | AY32: -1 | AZ32: -1 | BA32: -1 | BB32: -1 | BC32: -1 | BD32: -1 | BE32: -1 | BF32: -1 | BG32: -1 | BH32: -1 | BI32: -1 | BJ32: -1 | BK32: -1 | BL32: -1 | BM32: -1 | BN32: -1 | BO32: -1 | BP32: -1 | BQ32: -1 | BR32: -1 | BS32: -1 | BT32: -1 | BU32: -1 | BV32: -1 | BW32: -1 | BX32: -1 | BY32: -1 | BZ32: -1 | CA32: -1 | CB32: -1 | CC32: -1 | CD32: -1 | CE32: -1 | CF32: -1 | CG32: -1 | CH32: -1 | CI32: -1 | CJ32: -1 | CK32: -1 | CL32: -1 | CM32: -1 | CN32: -1 | CO32: -1 | CP32: -1 | CQ32: -1 | CR32: -1 | CS32: -1 | CT32: -1 | CU32: -1 | CV32: -1 | CW32: -1 | CX32: -1 | CY32: -1 | CZ32: -1 | DA32: -1 | DB32: -1 | DC32: -1 | DD32: -1 | DE32: -1 | DF32: -1 | DG32: -1 | DH32: -1 | DI32: -1 | DJ32: -1 | DK32: -1 | DL32: -1 | DM32: -1 | DN32: -1 | DO32: -1 | DP32: -1 | DQ32: -1 | DR32: -1 | DS32: -1 | DT32: -1 | DU32: -1 | DV32: -1 | DW32: -1 | DX32: -1 | DY32: -1 | DZ32: -1 | EA32: -1 | EB32: -1 | EC32: -1 | ED32: -1 | EE32: -1 | EF32: -1 | EG32: -1 | EH32: -1 | EI32: -1 | EJ32: -1 | EK32: -1 | EL32: -1 | EM32: -1 | EN32: -1 | EO32: -1 | EP32: -1 | EQ32: -1 | ER32: -1 | ES32: -1 | ET32: -1 | EU32: -1 | EV32: -1 | EW32: -1 | EX32: -1 | EY32: -1 | EZ32: -1 | FA32: -1 | FB32: -1 | FC32: -1 | FD32: -1 | FE32: -1 | FF32: -1 | FG32: -1 | FH32: -1 | FI32: -1 | FJ32: -1 | FK32: -1 | FL32: -1 | FM32: -1 | FN32: -1 | FO32: -1 | FP32: -1 | FQ32: -1 | FR32: -1 | FS32: -1 | FT32: -1 | FU32: -1 | FV32: -1 | FW32: -1 | FX32: -1 | FY32: -1 | FZ32: -1 | GA32: -1 | GB32: -1 | GC32: -1 | GD32: -1 | GE32: -1 | GF32: -1 | GG32: -1 | GH32: -1 | GI32: -1 | GJ32: -1 | GK32: -1 | GL32: -1 | GM32: -1 | GN32: -1 | GO32: -1 | GP32: -1 | GQ32: -1 | GR32: -1 | GS32: -1 | GT32: -1 | GU32: -1 | GV32: -1 | GW32: -1 | GX32: -1 | GY32: -1 | GZ32: -1 | HA32: -1 | HB32: -1 | HC32: -1 | HD32: -1 | HE32: -1 | HF32: -1 | HG32: -1 | HH32: -1 | HI32: -1 | HJ32: -1 | HK32: -1 | HL32: -1 | HM32: -1 | HN32: -1 | HO32: -1 | HP32: -1 | HQ32: -1 | HR32: -1 | HS32: -1 | HT32: -1 | HU32: -1 | HV32: -1 | HW32: -1 | HX32: -1 | HY32: -1 | HZ32: -1 | IA32: -1 | IB32: -1 | IC32: -1 | ID32: -1 | IE32: -1 | IF32: -1 | IG32: -1 | IH32: -1 | II32: -1 | IJ32: -1 | IK32: -1 | IL32: -1 | IM32: -1 | IN32: -1 | IO32: -1 | IP32: -1 | IQ32: -1 | IR32: -1 | IS32: -1 | IT32: -1 | IU32: -1 | IV32: -1 | IW32: -1 | IX32: -1 | IY32: -1 | IZ32: -1 | JA32: -1 | JB32: -1 | JC32: -1 | JD32: -1 | JE32: -1 | JF32: -1 | JG32: -1 | JH32: -1 | JI32: -1 | JJ32: -1 | JK32: -1 | JL32: -1 | JM32: -1 | JN32: -1 | JO32: -1 | JP32: -1 | JQ32: -1 | JR32: -1 | JS32: -1 | JT32: -1 | JU32: -1 | JV32: -1 | JW32: -1 | JX32: -1 | JY32: -1 | JZ32: -1 | KA32: -1 | KB32: -1 | KC32: -1 | KD32: -1 | KE32: -1 | KF32: -1 | KG32: -1 | KH32: -1 | KI32: -1 | KJ32: -1 | KK32: -1 | KL32: -1 | KM32: -1 | KN32: -1 | KO32: -1 | KP32: -1 | KQ32: -1 | KR32: -1 | KS32: -1 | KT32: -1 | KU32: -1 | KV32: -1 | KW32: -1 | KX32: -1 | KY32: -1 | KZ32: -1 | LA32: -1 | LB32: -1 | LC32: -1 | LD32: -1 | LE32: -1 | LF32: -1 | LG32: -1 | LH32: -1 | LI32: -1 | LJ32: -1 | LK32: -1 | LL32: -1 | LM32: -1 | LN32: -1 | LO32: -1 | LP32: -1 | LQ32: -1 | LR32: -1 | LS32: -1 | LT32: -1 | LU32: -1 | LV32: -1 | LW32: -1 | LX32: -1 | LY32: -1 | LZ32: -1 | MA32: -1 | MB32: -1 | MC32: -1 | MD32: -1 | ME32: -1 | MF32: -1 | MG32: -1 | MH32: -1 | MI32: -1 | MJ32: -1 | MK32: -1 | ML32: -1 | MM32: -1 | MN32: -1 | MO32: -1 | MP32: -1 | MQ32: -1 | MR32: -1 | MS32: -1 | MT32: -1 | MU32: -1 | MV32: -1 | MW32: -1 | MX32: -1 | MY32: -1 | MZ32: -1 | NA32: -1 | NB32: -1 | NC32: -1 | ND32: -1 | NE32: -1 | NF32: -1 | NG32: -1 | NH32: -1 | NI32: -1 | NJ32: -1 | NK32: -1 | NL32: -1 | NM32: -1 | NN32: -1 | NO32: -1 | NP32: -1 | NQ32: -1 | NR32: -1 | NS32: -1 | NT32: -1 | NU32: -1 | NV32: -1 | NW32: -1 | NX32: -1 | NY32: -1 | NZ32: -1 | OA32: -1 | OB32: -1 | OC32: -1 | OD32: -1 | OE32: -1 | OF32: -1 | OG32: -1 | OH32: -1 | OI32: -1 | OJ32: -1 | OK32: -1 | OL32: -1
A33: 1.92 | B33: -1 | C33: -1 | D33: -1 | E33: -1 | F33: -1 | G33: -1 | H33: -1 | I33: -1 | J33: -1 | K33: -1 | L33: -1 | M33: -1 | N33: -1 | O33: -1 | P33: -1 | Q33: -1 | R33: -1 | S33: -1 | T33: -1 | U33: -1 | V33: -1 | W33: -1 | X33: -1 | Y33: -1 | Z33: -1 | AA33: -1 | AB33: -1 | AC33: -1 | AD33: -1 | AE33: -1 | AF33: -1 | AG33: -1 | AH33: -1 | AI33: -1 | AJ33: -1 | AK33: -1 | AL33: -1 | AM33: -1 | AN33: -1 | AO33: -1 | AP33: -1 | AQ33: -1 | AR33: -1 | AS33: -1 | AT33: -1 | AU33: -1 | AV33: -1 | AW33: -1 | AX33: -1 | AY33: -1 | AZ33: -1 | BA33: -1 | BB33: -1 | BC33: -1 | BD33: -1 | BE33: -1 | BF33: -1 | BG33: -1 | BH33: -1 | BI33: -1 | BJ33: -1 | BK33: -1 | BL33: -1 | BM33: -1 | BN33: -1 | BO33: -1 | BP33: -1 | BQ33: -1 | BR33: -1 | BS33: -1 | BT33: -1 | BU33: -1 | BV33: -1 | BW33: -1 | BX33: -1 | BY33: -1 | BZ33: -1 | CA33: -1 | CB33: -1 | CC33: -1 | CD33: -1 | CE33: -1 | CF33: -1 | CG33: -1 | CH33: -1 | CI33: -1 | CJ33: -1 | CK33: -1 | CL33: -1 | CM33: -1 | CN33: -1 | CO33: -1 | CP33: -1 | CQ33: -1 | CR33: -1 | CS33: -1 | CT33: -1 | CU33: -1 | CV33: -1 | CW33: -1 | CX33: -1 | CY33: -1 | CZ33: -1 | DA33: -1 | DB33: -1 | DC33: -1 | DD33: -1 | DE33: -1 | DF33: -1 | DG33: -1 | DH33: -1 | DI33: -1 | DJ33: -1 | DK33: -1 | DL33: -1 | DM33: -1 | DN33: -1 | DO33: -1 | DP33: -1 | DQ33: -1 | DR33: -1 | DS33: -1 | DT33: -1 | DU33: -1 | DV33: -1 | DW33: -1 | DX33: -1 | DY33: -1 | DZ33: -1 | EA33: -1 | EB33: -1 | EC33: -1 | ED33: -1 | EE33: -1 | EF33: -1 | EG33: -1 | EH33: -1 | EI33: -1 | EJ33: -1 | EK33: -1 | EL33: -1 | EM33: -1 | EN33: -1 | EO33: -1 | EP33: -1 | EQ33: -1 | ER33: -1 | ES33: -1 | ET33: -1 | EU33: -1 | EV33: -1 | EW33: -1 | EX33: -1 | EY33: -1 | EZ33: -1 | FA33: -1 | FB33: -1 | FC33: -1 | FD33: -1 | FE33: -1 | FF33: -1 | FG33: -1 | FH33: -1 | FI33: -1 | FJ33: -1 | FK33: -1 | FL33: -1 | FM33: -1 | FN33: -1 | FO33: -1 | FP33: -1 | FQ33: -1 | FR33: -1 | FS33: -1 | FT33: -1 | FU33: -1 | FV33: -1 | FW33: -1 | FX33: -1 | FY33: -1 | FZ33: -1 | GA33: -1 | GB33: -1 | GC33: -1 | GD33: -1 | GE33: -1 | GF33: -1 | GG33: -1 | GH33: -1 | GI33: -1 | GJ33: -1 | GK33: -1 | GL33: -1 | GM33: -1 | GN33: -1 | GO33: -1 | GP33: -1 | GQ33: -1 | GR33: -1 | GS33: -1 | GT33: -1 | GU33: -1 | GV33: -1 | GW33: -1 | GX33: -1 | GY33: -1 | GZ33: -1 | HA33: -1 | HB33: -1 | HC33: -1 | HD33: -1 | HE33: -1 | HF33: -1 | HG33: -1 | HH33: -1 | HI33: -1 | HJ33: -1 | HK33: -1 | HL33: -1 | HM33: -1 | HN33: -1 | HO33: -1 | HP33: -1 | HQ33: -1 | HR33: -1 | HS33: -1 | HT33: -1 | HU33: -1 | HV33: -1 | HW33: -1 | HX33: -1 | HY33: -1 | HZ33: -1 | IA33: -1 | IB33: -1 | IC33: -1 | ID33: -1 | IE33: -1 | IF33: -1 | IG33: -1 | IH33: -1 | II33: -1 | IJ33: -1 | IK33: -1 | IL33: -1 | IM33: -1 | IN33: -1 | IO33: -1 | IP33: -1 | IQ33: -1 | IR33: -1 | IS33: -1 | IT33: -1 | IU33: -1 | IV33: -1 | IW33: -1 | IX33: -1 | IY33: -1 | IZ33: -1 | JA33: -1 | JB33: -1 | JC33: -1 | JD33: -1 | JE33: -1 | JF33: -1 | JG33: -1 | JH33: -1 | JI33: -1 | JJ33: -1 | JK33: -1 | JL33: -1 | JM33: -1 | JN33: -1 | JO33: -1 | JP33: -1 | JQ33: -1 | JR33: -1 | JS33: -1 | JT33: -1 | JU33: -1 | JV33: -1 | JW33: -1 | JX33: -1 | JY33: -1 | JZ33: -1 | KA33: -1 | KB33: -1 | KC33: -1 | KD33: -1 | KE33: -1 | KF33: -1 | KG33: -1 | KH33: -1 | KI33: -1 | KJ33: -1 | KK33: -1 | KL33: -1 | KM33: -1 | KN33: -1 | KO33: -1 | KP33: -1 | KQ33: -1 | KR33: -1 | KS33: -1 | KT33: -1 | KU33: -1 | KV33: -1 | KW33: -1 | KX33: -1 | KY33: -1 | KZ33: -1 | LA33: -1 | LB33: -1 | LC33: -1 | LD33: -1 | LE33: -1 | LF33: -1 | LG33: -1 | LH33: -1 | LI33: -1 | LJ33: -1 | LK33: -1 | LL33: -1 | LM33: -1 | LN33: -1 | LO33: -1 | LP33: -1 | LQ33: -1 | LR33: -1 | LS33: -1 | LT33: -1 | LU33: -1 | LV33: -1 | LW33: -1 | LX33: -1 | LY33: -1 | LZ33: -1 | MA33: -1 | MB33: -1 | MC33: -1 | MD33: -1 | ME33: -1 | MF33: -1 | MG33: -1 | MH33: -1 | MI33: -1 | MJ33: -1 | MK33: -1 | ML33: -1 | MM33: -1 | MN33: -1 | MO33: -1 | MP33: -1 | MQ33: -1 | MR33: -1 | MS33: -1 | MT33: -1 | MU33: -1 | MV33: -1 | MW33: -1 | MX33: -1 | MY33: -1 | MZ33: -1 | NA33: -1 | NB33: -1 | NC33: -1 | ND33: -1 | NE33: -1 | NF33: -1 | NG33: -1 | NH33: -1 | NI33: -1 | NJ33: -1 | NK33: -1 | NL33: -1 | NM33: -1 | NN33: -1 | NO33: -1 | NP33: -1 | NQ33: -1 | NR33: -1 | NS33: -1 | NT33: -1 | NU33: -1 | NV33: -1 | NW33: -1 | NX33: -1 | NY33: -1 | NZ33: -1 | OA33: -1 | OB33: -1 | OC33: -1 | OD33: -1 | OE33: -1 | OF33: -1 | OG33: -1 | OH33: -1 | OI33: -1 | OJ33: -1 | OK33: -1 | OL33: -1
A34: 1.91 | B34: -1 | C34: -1 | D34: -1 | E34: -1 | F34: -1 | G34: -1 | H34: -1 | I34: -1 | J34: -1 | K34: -1 | L34: -1 | M34: -1 | N34: -1 | O34: -1 | P34: -1 | Q34: -1 | R34: -1 | S34: -1 | T34: -1 | U34: -1 | V34: -1 | W34: -1 | X34: -1 | Y34: -1 | Z34: -1 | AA34: -1 | AB34: -1 | AC34: -1 | AD34: -1 | AE34: -1 | AF34: -1 | AG34: -1 | AH34: -1 | AI34: -1 | AJ34: -1 | AK34: -1 | AL34: -1 | AM34: -1 | AN34: -1 | AO34: -1 | AP34: -1 | AQ34: -1 | AR34: -1 | AS34: -1 | AT34: -1 | AU34: -1 | AV34: -1 | AW34: -1 | AX34: -1 | AY34: -1 | AZ34: -1 | BA34: -1 | BB34: -1 | BC34: -1 | BD34: -1 | BE34: -1 | BF34: -1 | BG34: -1 | BH34: -1 | BI34: -1 | BJ34: -1 | BK34: -1 | BL34: -1 | BM34: -1 | BN34: -1 | BO34: -1 | BP34: -1 | BQ34: -1 | BR34: -1 | BS34: -1 | BT34: -1 | BU34: -1 | BV34: -1 | BW34: -1 | BX34: -1 | BY34: -1 | BZ34: -1 | CA34: -1 | CB34: -1 | CC34: -1 | CD34: -1 | CE34: -1 | CF34: -1 | CG34: -1 | CH34: -1 | CI34: -1 | CJ34: -1 | CK34: -1 | CL34: -1 | CM34: -1 | CN34: -1 | CO34: -1 | CP34: -1 | CQ34: -1 | CR34: -1 | CS34: -1 | CT34: -1 | CU34: -1 | CV34: -1 | CW34: -1 | CX34: -1 | CY34: -1 | CZ34: -1 | DA34: -1 | DB34: -1 | DC34: -1 | DD34: -1 | DE34: -1 | DF34: -1 | DG34: -1 | DH34: -1 | DI34: -1 | DJ34: -1 | DK34: -1 | DL34: -1 | DM34: -1 | DN34: -1 | DO34: -1 | DP34: -1 | DQ34: -1 | DR34: -1 | DS34: -1 | DT34: -1 | DU34: -1 | DV34: -1 | DW34: -1 | DX34: -1 | DY34: -1 | DZ34: -1 | EA34: -1 | EB34: -1 | EC34: -1 | ED34: -1 | EE34: -1 | EF34: -1 | EG34: -1 | EH34: -1 | EI34: -1 | EJ34: -1 | EK34: -1 | EL34: -1 | EM34: -1 | EN34: -1 | EO34: -1 | EP34: -1 | EQ34: -1 | ER34: -1 | ES34: -1 | ET34: -1 | EU34: -1 | EV34: -1 | EW34: -1 | EX34: -1 | EY34: -1 | EZ34: -1 | FA34: -1 | FB34: -1 | FC34: -1 | FD34: -1 | FE34: -1 | FF34: -1 | FG34: -1 | FH34: -1 | FI34: -1 | FJ34: -1 | FK34: -1 | FL34: -1 | FM34: -1 | FN34: -1 | FO34: -1 | FP34: -1 | FQ34: -1 | FR34: -1 | FS34: -1 | FT34: -1 | FU34: -1 | FV34: -1 | FW34: -1 | FX34: -1 | FY34: -1 | FZ34: -1 | GA34: -1 | GB34: -1 | GC34: -1 | GD34: -1 | GE34: -1 | GF34: -1 | GG34: -1 | GH34: -1 | GI34: -1 | GJ34: -1 | GK34: -1 | GL34: -1 | GM34: -1 | GN34: -1 | GO34: -1 | GP34: -1 | GQ34: -1 | GR34: -1 | GS34: -1 | GT34: -1 | GU34: -1 | GV34: -1 | GW34: -1 | GX34: -1 | GY34: -1 | GZ34: -1 | HA34: -1 | HB34: -1 | HC34: -1 | HD34: -1 | HE34: -1 | HF34: -1 | HG34: -1 | HH34: -1 | HI34: -1 | HJ34: -1 | HK34: -1 | HL34: -1 | HM34: -1 | HN34: -1 | HO34: -1 | HP34: -1 | HQ34: -1 | HR34: -1 | HS34: -1 | HT34: -1 | HU34: -1 | HV34: -1 | HW34: -1 | HX34: -1 | HY34: -1 | HZ34: -1 | IA34: -1 | IB34: -1 | IC34: -1 | ID34: -1 | IE34: -1 | IF34: -1 | IG34: -1 | IH34: -1 | II34: -1 | IJ34: -1 | IK34: -1 | IL34: -1 | IM34: -1 | IN34: -1 | IO34: -1 | IP34: -1 | IQ34: -1 | IR34: -1 | IS34: -1 | IT34: -1 | IU34: -1 | IV34: -1 | IW34: -1 | IX34: -1 | IY34: -1 | IZ34: -1 | JA34: -1 | JB34: -1 | JC34: -1 | JD34: -1 | JE34: -1 | JF34: -1 | JG34: -1 | JH34: -1 | JI34: -1 | JJ34: -1 | JK34: -1 | JL34: -1 | JM34: -1 | JN34: -1 | JO34: -1 | JP34: -1 | JQ34: -1 | JR34: -1 | JS34: -1 | JT34: -1 | JU34: -1 | JV34: -1 | JW34: -1 | JX34: -1 | JY34: -1 | JZ34: -1 | KA34: -1 | KB34: -1 | KC34: -1 | KD34: -1 | KE34: -1 | KF34: -1 | KG34: -1 | KH34: -1 | KI34: -1 | KJ34: -1 | KK34: -1 | KL34: -1 | KM34: -1 | KN34: -1 | KO34: -1 | KP34: -1 | KQ34: -1 | KR34: -1 | KS34: -1 | KT34: -1 | KU34: -1 | KV34: -1 | KW34: -1 | KX34: -1 | KY34: -1 | KZ34: -1 | LA34: -1 | LB34: -1 | LC34: -1 | LD34: -1 | LE34: -1 | LF34: -1 | LG34: -1 | LH34: -1 | LI34: -1 | LJ34: -1 | LK34: -1 | LL34: -1 | LM34: -1 | LN34: -1 | LO34: -1 | LP34: -1 | LQ34: -1 | LR34: -1 | LS34: -1 | LT34: -1 | LU34: -1 | LV34: -1 | LW34: -1 | LX34: -1 | LY34: -1 | LZ34: -1 | MA34: -1 | MB34: -1 | MC34: -1 | MD34: -1 | ME34: -1 | MF34: -1 | MG34: -1 | MH34: -1 | MI34: -1 | MJ34: -1 | MK34: -1 | ML34: -1 | MM34: -1 | MN34: -1 | MO34: -1 | MP34: -1 | MQ34: -1 | MR34: -1 | MS34: -1 | MT34: -1 | MU34: -1 | MV34: -1 | MW34: -1 | MX34: -1 | MY34: -1 | MZ34: -1 | NA34: -1 | NB34: -1 | NC34: -1 | ND34: -1 | NE34: -1 | NF34: -1 | NG34: -1 | NH34: -1 | NI34: -1 | NJ34: -1 | NK34: -1 | NL34: -1 | NM34: -1 | NN34: -1 | NO34: -1 | NP34: -1 | NQ34: -1 | NR34: -1 | NS34: -1 | NT34: -1 | NU34: -1 | NV34: -1 | NW34: -1 | NX34: -1 | NY34: -1 | NZ34: -1 | OA34: -1 | OB34: -1 | OC34: -1 | OD34: -1 | OE34: -1 | OF34: -1 | OG34: -1 | OH34: -1 | OI34: -1 | OJ34: -1 | OK34: -1 | OL34: -1
